[05/Oct/2014 07:55:01] INFO [sos_app.views:18] about to test
[05/Oct/2014 07:55:43] INFO [sos_app.views:18] about to test
[05/Oct/2014 07:56:23] INFO [sos_app.views:18] <class 'sos_app.permissions.IsOwner'>
[05/Oct/2014 07:56:36] INFO [sos_app.views:18] about to test
[05/Oct/2014 07:58:16] INFO [sos_app.permissions:14] Contacts object
[05/Oct/2014 07:58:16] INFO [sos_app.permissions:15] prateek
[05/Oct/2014 07:58:21] INFO [sos_app.permissions:14] Contacts object
[05/Oct/2014 07:58:21] INFO [sos_app.permissions:15] AnonymousUser
[05/Oct/2014 07:58:29] INFO [sos_app.permissions:14] Contacts object
[05/Oct/2014 07:58:29] INFO [sos_app.permissions:15] admin
[05/Oct/2014 07:58:29] INFO [sos_app.permissions:14] Contacts object
[05/Oct/2014 07:58:29] INFO [sos_app.permissions:15] admin
[05/Oct/2014 07:58:29] INFO [sos_app.permissions:14] Contacts object
[05/Oct/2014 07:58:29] INFO [sos_app.permissions:15] admin
[05/Oct/2014 07:58:29] INFO [sos_app.permissions:14] Contacts object
[05/Oct/2014 07:58:29] INFO [sos_app.permissions:15] admin
[05/Oct/2014 07:58:29] INFO [sos_app.permissions:14] Contacts object
[05/Oct/2014 07:58:29] INFO [sos_app.permissions:15] admin
[05/Oct/2014 07:58:29] INFO [sos_app.permissions:14] Contacts object
[05/Oct/2014 07:58:29] INFO [sos_app.permissions:15] admin
[05/Oct/2014 08:00:06] INFO [sos_app.views:18] about to test
[05/Oct/2014 08:00:06] ERROR [django.request:224] Internal Server Error: /contacts/
Traceback (most recent call last):
  File "/Library/Python/2.7/site-packages/django/core/handlers/base.py", line 112, in get_response
    response = wrapped_callback(request, *callback_args, **callback_kwargs)
  File "/Library/Python/2.7/site-packages/django/views/decorators/csrf.py", line 57, in wrapped_view
    return view_func(*args, **kwargs)
  File "/Library/Python/2.7/site-packages/rest_framework/viewsets.py", line 79, in view
    return self.dispatch(request, *args, **kwargs)
  File "/Library/Python/2.7/site-packages/rest_framework/views.py", line 405, in dispatch
    self.response = self.finalize_response(request, response, *args, **kwargs)
  File "/Library/Python/2.7/site-packages/rest_framework/views.py", line 336, in finalize_response
    % type(response)
AssertionError: Expected a `Response`, `HttpResponse` or `HttpStreamingResponse` to be returned from the view, but received a `<type 'NoneType'>`
[05/Oct/2014 08:04:46] INFO [sos_app.views:19] about to test
[05/Oct/2014 08:04:46] ERROR [django.request:224] Internal Server Error: /contacts/
Traceback (most recent call last):
  File "/Library/Python/2.7/site-packages/django/core/handlers/base.py", line 112, in get_response
    response = wrapped_callback(request, *callback_args, **callback_kwargs)
  File "/Library/Python/2.7/site-packages/django/views/decorators/csrf.py", line 57, in wrapped_view
    return view_func(*args, **kwargs)
  File "/Library/Python/2.7/site-packages/rest_framework/viewsets.py", line 79, in view
    return self.dispatch(request, *args, **kwargs)
  File "/Library/Python/2.7/site-packages/rest_framework/views.py", line 405, in dispatch
    self.response = self.finalize_response(request, response, *args, **kwargs)
  File "/Library/Python/2.7/site-packages/rest_framework/views.py", line 336, in finalize_response
    % type(response)
AssertionError: Expected a `Response`, `HttpResponse` or `HttpStreamingResponse` to be returned from the view, but received a `<type 'NoneType'>`
[05/Oct/2014 08:04:56] INFO [sos_app.views:19] about to test
[05/Oct/2014 08:05:02] INFO [sos_app.permissions:14] Contacts object
[05/Oct/2014 08:05:02] INFO [sos_app.permissions:15] prateek
[05/Oct/2014 08:05:06] INFO [sos_app.permissions:14] Contacts object
[05/Oct/2014 08:05:06] INFO [sos_app.permissions:15] AnonymousUser
[05/Oct/2014 08:05:12] INFO [sos_app.permissions:14] Contacts object
[05/Oct/2014 08:05:12] INFO [sos_app.permissions:15] admin
[05/Oct/2014 08:05:12] INFO [sos_app.permissions:14] Contacts object
[05/Oct/2014 08:05:12] INFO [sos_app.permissions:15] admin
[05/Oct/2014 08:05:12] INFO [sos_app.permissions:14] Contacts object
[05/Oct/2014 08:05:12] INFO [sos_app.permissions:15] admin
[05/Oct/2014 08:07:40] INFO [sos_app.permissions:14] Contacts object
[05/Oct/2014 08:07:40] INFO [sos_app.permissions:15] admin
[05/Oct/2014 08:07:40] INFO [sos_app.permissions:14] Contacts object
[05/Oct/2014 08:07:40] INFO [sos_app.permissions:15] admin
[05/Oct/2014 08:07:40] INFO [sos_app.permissions:14] Contacts object
[05/Oct/2014 08:07:40] INFO [sos_app.permissions:15] admin
[05/Oct/2014 08:08:14] INFO [sos_app.views:19] about to test
[05/Oct/2014 08:08:14] INFO [sos_app.permissions:14] Contacts object
[05/Oct/2014 08:08:14] INFO [sos_app.permissions:15] admin
[05/Oct/2014 08:08:15] INFO [sos_app.permissions:14] Contacts object
[05/Oct/2014 08:08:15] INFO [sos_app.permissions:15] admin
[05/Oct/2014 08:08:15] INFO [sos_app.permissions:14] Contacts object
[05/Oct/2014 08:08:15] INFO [sos_app.permissions:15] admin
[05/Oct/2014 08:08:15] INFO [sos_app.permissions:14] Contacts object
[05/Oct/2014 08:08:15] INFO [sos_app.permissions:15] admin
[05/Oct/2014 08:08:15] INFO [sos_app.permissions:14] Contacts object
[05/Oct/2014 08:08:15] INFO [sos_app.permissions:15] admin
[05/Oct/2014 08:08:15] INFO [sos_app.permissions:14] Contacts object
[05/Oct/2014 08:08:15] INFO [sos_app.permissions:15] admin
[05/Oct/2014 08:12:51] INFO [sos_app.views:19] about to test
[05/Oct/2014 08:12:51] ERROR [django.request:224] Internal Server Error: /contacts/1/
Traceback (most recent call last):
  File "/Library/Python/2.7/site-packages/django/core/handlers/base.py", line 112, in get_response
    response = wrapped_callback(request, *callback_args, **callback_kwargs)
  File "/Library/Python/2.7/site-packages/django/views/decorators/csrf.py", line 57, in wrapped_view
    return view_func(*args, **kwargs)
  File "/Library/Python/2.7/site-packages/rest_framework/viewsets.py", line 79, in view
    return self.dispatch(request, *args, **kwargs)
  File "/Library/Python/2.7/site-packages/rest_framework/views.py", line 403, in dispatch
    response = self.handle_exception(exc)
  File "/Library/Python/2.7/site-packages/rest_framework/views.py", line 391, in dispatch
    self.initial(request, *args, **kwargs)
  File "/Library/Python/2.7/site-packages/rest_framework/views.py", line 321, in initial
    self.check_permissions(request)
  File "/Library/Python/2.7/site-packages/rest_framework/views.py", line 277, in check_permissions
    for permission in self.get_permissions():
  File "/Library/Python/2.7/site-packages/rest_framework/views.py", line 230, in get_permissions
    return [permission() for permission in self.permission_classes]
TypeError: 'module' object is not callable
[05/Oct/2014 08:13:04] INFO [sos_app.views:19] about to test
[05/Oct/2014 08:13:04] INFO [sos_app.permissions:14] Contacts object
[05/Oct/2014 08:13:04] INFO [sos_app.permissions:15] AnonymousUser
[05/Oct/2014 08:13:10] INFO [sos_app.permissions:14] Contacts object
[05/Oct/2014 08:13:10] INFO [sos_app.permissions:15] prateek
[05/Oct/2014 08:13:51] ERROR [django.request:224] Internal Server Error: /contacts/
Traceback (most recent call last):
  File "/Library/Python/2.7/site-packages/django/core/handlers/base.py", line 112, in get_response
    response = wrapped_callback(request, *callback_args, **callback_kwargs)
  File "/Library/Python/2.7/site-packages/django/views/decorators/csrf.py", line 57, in wrapped_view
    return view_func(*args, **kwargs)
  File "/Library/Python/2.7/site-packages/rest_framework/viewsets.py", line 79, in view
    return self.dispatch(request, *args, **kwargs)
  File "/Library/Python/2.7/site-packages/rest_framework/views.py", line 403, in dispatch
    response = self.handle_exception(exc)
  File "/Library/Python/2.7/site-packages/rest_framework/views.py", line 400, in dispatch
    response = handler(request, *args, **kwargs)
  File "/Library/Python/2.7/site-packages/rest_framework/mixins.py", line 54, in create
    self.object = serializer.save(force_insert=True)
  File "/Library/Python/2.7/site-packages/rest_framework/serializers.py", line 595, in save
    self.save_object(self.object, **kwargs)
  File "/Library/Python/2.7/site-packages/rest_framework/serializers.py", line 1037, in save_object
    obj.save(**kwargs)
  File "/Library/Python/2.7/site-packages/django/db/models/base.py", line 545, in save
    force_update=force_update, update_fields=update_fields)
  File "/Library/Python/2.7/site-packages/django/db/models/base.py", line 573, in save_base
    updated = self._save_table(raw, cls, force_insert, force_update, using, update_fields)
  File "/Library/Python/2.7/site-packages/django/db/models/base.py", line 654, in _save_table
    result = self._do_insert(cls._base_manager, using, fields, update_pk, raw)
  File "/Library/Python/2.7/site-packages/django/db/models/base.py", line 687, in _do_insert
    using=using, raw=raw)
  File "/Library/Python/2.7/site-packages/django/db/models/manager.py", line 232, in _insert
    return insert_query(self.model, objs, fields, **kwargs)
  File "/Library/Python/2.7/site-packages/django/db/models/query.py", line 1514, in insert_query
    return query.get_compiler(using=using).execute_sql(return_id)
  File "/Library/Python/2.7/site-packages/django/db/models/sql/compiler.py", line 903, in execute_sql
    cursor.execute(sql, params)
  File "/Library/Python/2.7/site-packages/django/db/backends/util.py", line 69, in execute
    return super(CursorDebugWrapper, self).execute(sql, params)
  File "/Library/Python/2.7/site-packages/django/db/backends/util.py", line 53, in execute
    return self.cursor.execute(sql, params)
  File "/Library/Python/2.7/site-packages/django/db/utils.py", line 99, in __exit__
    six.reraise(dj_exc_type, dj_exc_value, traceback)
  File "/Library/Python/2.7/site-packages/django/db/backends/util.py", line 53, in execute
    return self.cursor.execute(sql, params)
  File "/Library/Python/2.7/site-packages/django/db/backends/mysql/base.py", line 124, in execute
    return self.cursor.execute(query, args)
  File "/Library/Python/2.7/site-packages/MySQLdb/cursors.py", line 205, in execute
    self.errorhandler(self, exc, value)
  File "/Library/Python/2.7/site-packages/MySQLdb/connections.py", line 36, in defaulterrorhandler
    raise errorclass, errorvalue
IntegrityError: (1452, 'Cannot add or update a child row: a foreign key constraint fails (`sos`.`sos_app_contacts`, CONSTRAINT `user_id_id_refs_id_e19b8f99` FOREIGN KEY (`user_id_id`) REFERENCES `sos_app_users` (`id`))')
[05/Oct/2014 08:20:24] INFO [sos_app.views:19] about to test
[05/Oct/2014 08:21:01] INFO [sos_app.permissions:14] Contacts object
[05/Oct/2014 08:21:01] INFO [sos_app.permissions:15] prateek
[05/Oct/2014 08:21:01] ERROR [django.request:224] Internal Server Error: /contacts/
Traceback (most recent call last):
  File "/Library/Python/2.7/site-packages/django/core/handlers/base.py", line 137, in get_response
    response = response.render()
  File "/Library/Python/2.7/site-packages/django/template/response.py", line 105, in render
    self.content = self.rendered_content
  File "/Library/Python/2.7/site-packages/rest_framework/response.py", line 63, in rendered_content
    ret = renderer.render(self.data, media_type, context)
  File "/Library/Python/2.7/site-packages/rest_framework/renderers.py", line 606, in render
    context = self.get_context(data, accepted_media_type, renderer_context)
  File "/Library/Python/2.7/site-packages/rest_framework/renderers.py", line 556, in get_context
    raw_data_post_form = self.get_raw_data_form(view, 'POST', request)
  File "/Library/Python/2.7/site-packages/rest_framework/renderers.py", line 484, in get_raw_data_form
    if not self.show_form_for_method(view, method, request, obj):
  File "/Library/Python/2.7/site-packages/rest_framework/renderers.py", line 424, in show_form_for_method
    view.check_object_permissions(request, obj)
  File "/Library/Python/2.7/site-packages/rest_framework/views.py", line 287, in check_object_permissions
    if not permission.has_object_permission(request, self, obj):
  File "/Users/prateek/sjsu/sos/sos_app/permissions.py", line 16, in has_object_permission
    if obj.user_id == request.user:
AttributeError: 'Contacts' object has no attribute 'user_id'
[05/Oct/2014 08:21:32] INFO [sos_app.views:19] about to test
[05/Oct/2014 08:21:32] INFO [sos_app.permissions:14] Contacts object
[05/Oct/2014 08:21:32] INFO [sos_app.permissions:15] prateek
[05/Oct/2014 08:21:32] ERROR [django.request:224] Internal Server Error: /contacts/
Traceback (most recent call last):
  File "/Library/Python/2.7/site-packages/django/core/handlers/base.py", line 137, in get_response
    response = response.render()
  File "/Library/Python/2.7/site-packages/django/template/response.py", line 105, in render
    self.content = self.rendered_content
  File "/Library/Python/2.7/site-packages/rest_framework/response.py", line 63, in rendered_content
    ret = renderer.render(self.data, media_type, context)
  File "/Library/Python/2.7/site-packages/rest_framework/renderers.py", line 606, in render
    context = self.get_context(data, accepted_media_type, renderer_context)
  File "/Library/Python/2.7/site-packages/rest_framework/renderers.py", line 556, in get_context
    raw_data_post_form = self.get_raw_data_form(view, 'POST', request)
  File "/Library/Python/2.7/site-packages/rest_framework/renderers.py", line 484, in get_raw_data_form
    if not self.show_form_for_method(view, method, request, obj):
  File "/Library/Python/2.7/site-packages/rest_framework/renderers.py", line 424, in show_form_for_method
    view.check_object_permissions(request, obj)
  File "/Library/Python/2.7/site-packages/rest_framework/views.py", line 287, in check_object_permissions
    if not permission.has_object_permission(request, self, obj):
  File "/Users/prateek/sjsu/sos/sos_app/permissions.py", line 16, in has_object_permission
    if obj.user_id == request.user:
AttributeError: 'Contacts' object has no attribute 'user_id'
[05/Oct/2014 08:21:42] INFO [sos_app.permissions:14] Contacts object
[05/Oct/2014 08:21:42] INFO [sos_app.permissions:15] prateek
[05/Oct/2014 08:21:42] ERROR [django.request:224] Internal Server Error: /contacts/
Traceback (most recent call last):
  File "/Library/Python/2.7/site-packages/django/core/handlers/base.py", line 137, in get_response
    response = response.render()
  File "/Library/Python/2.7/site-packages/django/template/response.py", line 105, in render
    self.content = self.rendered_content
  File "/Library/Python/2.7/site-packages/rest_framework/response.py", line 63, in rendered_content
    ret = renderer.render(self.data, media_type, context)
  File "/Library/Python/2.7/site-packages/rest_framework/renderers.py", line 606, in render
    context = self.get_context(data, accepted_media_type, renderer_context)
  File "/Library/Python/2.7/site-packages/rest_framework/renderers.py", line 556, in get_context
    raw_data_post_form = self.get_raw_data_form(view, 'POST', request)
  File "/Library/Python/2.7/site-packages/rest_framework/renderers.py", line 484, in get_raw_data_form
    if not self.show_form_for_method(view, method, request, obj):
  File "/Library/Python/2.7/site-packages/rest_framework/renderers.py", line 424, in show_form_for_method
    view.check_object_permissions(request, obj)
  File "/Library/Python/2.7/site-packages/rest_framework/views.py", line 287, in check_object_permissions
    if not permission.has_object_permission(request, self, obj):
  File "/Users/prateek/sjsu/sos/sos_app/permissions.py", line 16, in has_object_permission
    if obj.user_id == request.user:
AttributeError: 'Contacts' object has no attribute 'user_id'
[05/Oct/2014 08:21:59] INFO [sos_app.permissions:14] Contacts object
[05/Oct/2014 08:21:59] INFO [sos_app.permissions:15] prateek
[05/Oct/2014 08:21:59] ERROR [django.request:224] Internal Server Error: /contacts/
Traceback (most recent call last):
  File "/Library/Python/2.7/site-packages/django/core/handlers/base.py", line 137, in get_response
    response = response.render()
  File "/Library/Python/2.7/site-packages/django/template/response.py", line 105, in render
    self.content = self.rendered_content
  File "/Library/Python/2.7/site-packages/rest_framework/response.py", line 63, in rendered_content
    ret = renderer.render(self.data, media_type, context)
  File "/Library/Python/2.7/site-packages/rest_framework/renderers.py", line 606, in render
    context = self.get_context(data, accepted_media_type, renderer_context)
  File "/Library/Python/2.7/site-packages/rest_framework/renderers.py", line 556, in get_context
    raw_data_post_form = self.get_raw_data_form(view, 'POST', request)
  File "/Library/Python/2.7/site-packages/rest_framework/renderers.py", line 484, in get_raw_data_form
    if not self.show_form_for_method(view, method, request, obj):
  File "/Library/Python/2.7/site-packages/rest_framework/renderers.py", line 424, in show_form_for_method
    view.check_object_permissions(request, obj)
  File "/Library/Python/2.7/site-packages/rest_framework/views.py", line 287, in check_object_permissions
    if not permission.has_object_permission(request, self, obj):
  File "/Users/prateek/sjsu/sos/sos_app/permissions.py", line 16, in has_object_permission
    if obj.user_id == request.user:
AttributeError: 'Contacts' object has no attribute 'user_id'
[05/Oct/2014 08:26:08] INFO [sos_app.views:19] about to test
[05/Oct/2014 08:26:09] INFO [sos_app.permissions:14] Contacts object
[05/Oct/2014 08:26:09] INFO [sos_app.permissions:15] prateek
[05/Oct/2014 08:26:09] ERROR [django.request:224] Internal Server Error: /contacts/
Traceback (most recent call last):
  File "/Library/Python/2.7/site-packages/django/core/handlers/base.py", line 137, in get_response
    response = response.render()
  File "/Library/Python/2.7/site-packages/django/template/response.py", line 105, in render
    self.content = self.rendered_content
  File "/Library/Python/2.7/site-packages/rest_framework/response.py", line 63, in rendered_content
    ret = renderer.render(self.data, media_type, context)
  File "/Library/Python/2.7/site-packages/rest_framework/renderers.py", line 606, in render
    context = self.get_context(data, accepted_media_type, renderer_context)
  File "/Library/Python/2.7/site-packages/rest_framework/renderers.py", line 556, in get_context
    raw_data_post_form = self.get_raw_data_form(view, 'POST', request)
  File "/Library/Python/2.7/site-packages/rest_framework/renderers.py", line 484, in get_raw_data_form
    if not self.show_form_for_method(view, method, request, obj):
  File "/Library/Python/2.7/site-packages/rest_framework/renderers.py", line 424, in show_form_for_method
    view.check_object_permissions(request, obj)
  File "/Library/Python/2.7/site-packages/rest_framework/views.py", line 287, in check_object_permissions
    if not permission.has_object_permission(request, self, obj):
  File "/Users/prateek/sjsu/sos/sos_app/permissions.py", line 16, in has_object_permission
    if obj.user_id == request.user:
AttributeError: 'Contacts' object has no attribute 'user_id'
[05/Oct/2014 08:26:27] INFO [sos_app.permissions:14] Contacts object
[05/Oct/2014 08:26:27] INFO [sos_app.permissions:15] prateek
[05/Oct/2014 08:26:27] ERROR [django.request:224] Internal Server Error: /contacts/
Traceback (most recent call last):
  File "/Library/Python/2.7/site-packages/django/core/handlers/base.py", line 137, in get_response
    response = response.render()
  File "/Library/Python/2.7/site-packages/django/template/response.py", line 105, in render
    self.content = self.rendered_content
  File "/Library/Python/2.7/site-packages/rest_framework/response.py", line 63, in rendered_content
    ret = renderer.render(self.data, media_type, context)
  File "/Library/Python/2.7/site-packages/rest_framework/renderers.py", line 606, in render
    context = self.get_context(data, accepted_media_type, renderer_context)
  File "/Library/Python/2.7/site-packages/rest_framework/renderers.py", line 556, in get_context
    raw_data_post_form = self.get_raw_data_form(view, 'POST', request)
  File "/Library/Python/2.7/site-packages/rest_framework/renderers.py", line 484, in get_raw_data_form
    if not self.show_form_for_method(view, method, request, obj):
  File "/Library/Python/2.7/site-packages/rest_framework/renderers.py", line 424, in show_form_for_method
    view.check_object_permissions(request, obj)
  File "/Library/Python/2.7/site-packages/rest_framework/views.py", line 287, in check_object_permissions
    if not permission.has_object_permission(request, self, obj):
  File "/Users/prateek/sjsu/sos/sos_app/permissions.py", line 16, in has_object_permission
    if obj.user_id == request.user:
AttributeError: 'Contacts' object has no attribute 'user_id'
[05/Oct/2014 08:26:48] INFO [sos_app.views:19] about to test
[05/Oct/2014 08:26:48] INFO [sos_app.permissions:14] Contacts object
[05/Oct/2014 08:26:48] INFO [sos_app.permissions:15] prateek
[05/Oct/2014 08:26:48] INFO [sos_app.permissions:14] Contacts object
[05/Oct/2014 08:26:48] INFO [sos_app.permissions:15] prateek
[05/Oct/2014 08:26:48] INFO [sos_app.permissions:14] Contacts object
[05/Oct/2014 08:26:48] INFO [sos_app.permissions:15] prateek
[05/Oct/2014 08:27:10] INFO [sos_app.permissions:14] Contacts object
[05/Oct/2014 08:27:10] INFO [sos_app.permissions:15] prateek
[05/Oct/2014 08:27:10] INFO [sos_app.permissions:14] Contacts object
[05/Oct/2014 08:27:10] INFO [sos_app.permissions:15] prateek
[05/Oct/2014 08:27:10] INFO [sos_app.permissions:14] Contacts object
[05/Oct/2014 08:27:10] INFO [sos_app.permissions:15] prateek
[05/Oct/2014 08:27:10] INFO [sos_app.permissions:14] Contacts object
[05/Oct/2014 08:27:10] INFO [sos_app.permissions:15] prateek
[05/Oct/2014 08:27:10] INFO [sos_app.permissions:14] Contacts object
[05/Oct/2014 08:27:10] INFO [sos_app.permissions:15] prateek
[05/Oct/2014 08:27:10] INFO [sos_app.permissions:14] Contacts object
[05/Oct/2014 08:27:10] INFO [sos_app.permissions:15] prateek
[05/Oct/2014 08:27:13] INFO [sos_app.permissions:14] Contacts object
[05/Oct/2014 08:27:13] INFO [sos_app.permissions:15] prateek
[05/Oct/2014 08:27:13] INFO [sos_app.permissions:14] Contacts object
[05/Oct/2014 08:27:13] INFO [sos_app.permissions:15] prateek
[05/Oct/2014 08:27:13] INFO [sos_app.permissions:14] Contacts object
[05/Oct/2014 08:27:13] INFO [sos_app.permissions:15] prateek
[05/Oct/2014 08:27:13] INFO [sos_app.permissions:14] Contacts object
[05/Oct/2014 08:27:13] INFO [sos_app.permissions:15] prateek
[05/Oct/2014 08:27:13] INFO [sos_app.permissions:14] Contacts object
[05/Oct/2014 08:27:13] INFO [sos_app.permissions:15] prateek
[05/Oct/2014 08:27:13] INFO [sos_app.permissions:14] Contacts object
[05/Oct/2014 08:27:13] INFO [sos_app.permissions:15] prateek
[05/Oct/2014 08:27:18] INFO [sos_app.permissions:14] Contacts object
[05/Oct/2014 08:27:18] INFO [sos_app.permissions:15] prateek
[05/Oct/2014 08:27:18] INFO [sos_app.permissions:14] Contacts object
[05/Oct/2014 08:27:18] INFO [sos_app.permissions:15] prateek
[05/Oct/2014 08:27:18] INFO [sos_app.permissions:14] Contacts object
[05/Oct/2014 08:27:18] INFO [sos_app.permissions:15] prateek
[05/Oct/2014 08:27:18] INFO [sos_app.permissions:14] Contacts object
[05/Oct/2014 08:27:18] INFO [sos_app.permissions:15] prateek
[05/Oct/2014 08:27:18] INFO [sos_app.permissions:14] Contacts object
[05/Oct/2014 08:27:18] INFO [sos_app.permissions:15] prateek
[05/Oct/2014 08:27:18] INFO [sos_app.permissions:14] Contacts object
[05/Oct/2014 08:27:18] INFO [sos_app.permissions:15] prateek
[05/Oct/2014 08:27:25] INFO [sos_app.permissions:14] Contacts object
[05/Oct/2014 08:27:25] INFO [sos_app.permissions:15] prateek
[05/Oct/2014 08:27:31] INFO [sos_app.permissions:14] Contacts object
[05/Oct/2014 08:27:31] INFO [sos_app.permissions:15] prateek
[05/Oct/2014 08:27:31] INFO [sos_app.permissions:14] Contacts object
[05/Oct/2014 08:27:31] INFO [sos_app.permissions:15] prateek
[05/Oct/2014 08:27:31] INFO [sos_app.permissions:14] Contacts object
[05/Oct/2014 08:27:31] INFO [sos_app.permissions:15] prateek
[05/Oct/2014 08:27:31] INFO [sos_app.permissions:14] Contacts object
[05/Oct/2014 08:27:31] INFO [sos_app.permissions:15] prateek
[05/Oct/2014 08:27:31] INFO [sos_app.permissions:14] Contacts object
[05/Oct/2014 08:27:31] INFO [sos_app.permissions:15] prateek
[05/Oct/2014 08:27:31] INFO [sos_app.permissions:14] Contacts object
[05/Oct/2014 08:27:31] INFO [sos_app.permissions:15] prateek
[05/Oct/2014 08:27:33] INFO [sos_app.permissions:14] Contacts object
[05/Oct/2014 08:27:33] INFO [sos_app.permissions:15] prateek
[05/Oct/2014 08:27:35] WARNING [django.request:143] Not Found: /contacts/5.
[05/Oct/2014 08:27:40] INFO [sos_app.permissions:14] Contacts object
[05/Oct/2014 08:27:40] INFO [sos_app.permissions:15] prateek
[05/Oct/2014 08:27:40] INFO [sos_app.permissions:14] Contacts object
[05/Oct/2014 08:27:40] INFO [sos_app.permissions:15] prateek
[05/Oct/2014 08:27:40] INFO [sos_app.permissions:14] Contacts object
[05/Oct/2014 08:27:40] INFO [sos_app.permissions:15] prateek
[05/Oct/2014 08:27:40] INFO [sos_app.permissions:14] Contacts object
[05/Oct/2014 08:27:40] INFO [sos_app.permissions:15] prateek
[05/Oct/2014 08:27:40] INFO [sos_app.permissions:14] Contacts object
[05/Oct/2014 08:27:40] INFO [sos_app.permissions:15] prateek
[05/Oct/2014 08:27:40] INFO [sos_app.permissions:14] Contacts object
[05/Oct/2014 08:27:40] INFO [sos_app.permissions:15] prateek
[05/Oct/2014 08:27:41] INFO [sos_app.permissions:14] Contacts object
[05/Oct/2014 08:27:41] INFO [sos_app.permissions:15] prateek
[05/Oct/2014 08:27:44] INFO [sos_app.permissions:14] Contacts object
[05/Oct/2014 08:27:44] INFO [sos_app.permissions:15] prateek
[05/Oct/2014 08:27:44] INFO [sos_app.permissions:14] Contacts object
[05/Oct/2014 08:27:44] INFO [sos_app.permissions:15] prateek
[05/Oct/2014 08:27:44] INFO [sos_app.permissions:14] Contacts object
[05/Oct/2014 08:27:44] INFO [sos_app.permissions:15] prateek
[05/Oct/2014 08:27:44] INFO [sos_app.permissions:14] Contacts object
[05/Oct/2014 08:27:44] INFO [sos_app.permissions:15] prateek
[05/Oct/2014 08:27:44] INFO [sos_app.permissions:14] Contacts object
[05/Oct/2014 08:27:44] INFO [sos_app.permissions:15] prateek
[05/Oct/2014 08:27:44] INFO [sos_app.permissions:14] Contacts object
[05/Oct/2014 08:27:44] INFO [sos_app.permissions:15] prateek
[05/Oct/2014 08:27:47] INFO [sos_app.permissions:14] Contacts object
[05/Oct/2014 08:27:47] INFO [sos_app.permissions:15] prateek
[05/Oct/2014 08:27:49] INFO [sos_app.permissions:14] Contacts object
[05/Oct/2014 08:27:49] INFO [sos_app.permissions:15] prateek
[05/Oct/2014 08:27:49] INFO [sos_app.permissions:14] Contacts object
[05/Oct/2014 08:27:49] INFO [sos_app.permissions:15] prateek
[05/Oct/2014 08:27:49] INFO [sos_app.permissions:14] Contacts object
[05/Oct/2014 08:27:49] INFO [sos_app.permissions:15] prateek
[05/Oct/2014 08:27:49] INFO [sos_app.permissions:14] Contacts object
[05/Oct/2014 08:27:49] INFO [sos_app.permissions:15] prateek
[05/Oct/2014 08:27:49] INFO [sos_app.permissions:14] Contacts object
[05/Oct/2014 08:27:49] INFO [sos_app.permissions:15] prateek
[05/Oct/2014 08:27:49] INFO [sos_app.permissions:14] Contacts object
[05/Oct/2014 08:27:49] INFO [sos_app.permissions:15] prateek
[05/Oct/2014 08:27:51] INFO [sos_app.permissions:14] Contacts object
[05/Oct/2014 08:27:51] INFO [sos_app.permissions:15] prateek
[05/Oct/2014 08:27:53] INFO [sos_app.permissions:14] Contacts object
[05/Oct/2014 08:27:53] INFO [sos_app.permissions:15] prateek
[05/Oct/2014 08:27:53] INFO [sos_app.permissions:14] Contacts object
[05/Oct/2014 08:27:53] INFO [sos_app.permissions:15] prateek
[05/Oct/2014 08:27:53] INFO [sos_app.permissions:14] Contacts object
[05/Oct/2014 08:27:53] INFO [sos_app.permissions:15] prateek
[05/Oct/2014 08:27:53] INFO [sos_app.permissions:14] Contacts object
[05/Oct/2014 08:27:53] INFO [sos_app.permissions:15] prateek
[05/Oct/2014 08:27:53] INFO [sos_app.permissions:14] Contacts object
[05/Oct/2014 08:27:53] INFO [sos_app.permissions:15] prateek
[05/Oct/2014 08:27:53] INFO [sos_app.permissions:14] Contacts object
[05/Oct/2014 08:27:53] INFO [sos_app.permissions:15] prateek
[05/Oct/2014 08:27:55] INFO [sos_app.permissions:14] Contacts object
[05/Oct/2014 08:27:55] INFO [sos_app.permissions:15] prateek
[05/Oct/2014 08:28:17] INFO [sos_app.permissions:14] Contacts object
[05/Oct/2014 08:28:17] INFO [sos_app.permissions:15] prateek
[05/Oct/2014 08:28:17] INFO [sos_app.permissions:14] Contacts object
[05/Oct/2014 08:28:17] INFO [sos_app.permissions:15] prateek
[05/Oct/2014 08:28:17] INFO [sos_app.permissions:14] Contacts object
[05/Oct/2014 08:28:17] INFO [sos_app.permissions:15] prateek
[05/Oct/2014 08:28:33] INFO [sos_app.permissions:14] Contacts object
[05/Oct/2014 08:28:33] INFO [sos_app.permissions:15] admin
[05/Oct/2014 08:47:17] ERROR [django.request:224] Internal Server Error: /incident
Traceback (most recent call last):
  File "/Library/Python/2.7/site-packages/django/core/handlers/base.py", line 88, in get_response
    response = middleware_method(request)
  File "/Library/Python/2.7/site-packages/django/middleware/common.py", line 71, in process_request
    if (not urlresolvers.is_valid_path(request.path_info, urlconf) and
  File "/Library/Python/2.7/site-packages/django/core/urlresolvers.py", line 600, in is_valid_path
    resolve(path, urlconf)
  File "/Library/Python/2.7/site-packages/django/core/urlresolvers.py", line 480, in resolve
    return get_resolver(urlconf).resolve(path)
  File "/Library/Python/2.7/site-packages/django/core/urlresolvers.py", line 337, in resolve
    for pattern in self.url_patterns:
  File "/Library/Python/2.7/site-packages/django/core/urlresolvers.py", line 365, in url_patterns
    patterns = getattr(self.urlconf_module, "urlpatterns", self.urlconf_module)
  File "/Library/Python/2.7/site-packages/django/core/urlresolvers.py", line 360, in urlconf_module
    self._urlconf_module = import_module(self.urlconf_name)
  File "/Library/Python/2.7/site-packages/django/utils/importlib.py", line 40, in import_module
    __import__(name)
  File "/Users/prateek/sjsu/sos/sos/urls.py", line 4, in <module>
    from sos_app.views import UserViewSet, ContactsViewSet, IncidentsReportedViewSet,\
  File "/Users/prateek/sjsu/sos/sos_app/views.py", line 5, in <module>
    from sos_app.models import Contacts, Mobile_Device, Incidents_Reported,\
ImportError: cannot import name IncidentsReportedSerializer
[05/Oct/2014 08:47:46] ERROR [django.request:224] Internal Server Error: /incident
Traceback (most recent call last):
  File "/Library/Python/2.7/site-packages/django/core/handlers/base.py", line 88, in get_response
    response = middleware_method(request)
  File "/Library/Python/2.7/site-packages/django/middleware/common.py", line 71, in process_request
    if (not urlresolvers.is_valid_path(request.path_info, urlconf) and
  File "/Library/Python/2.7/site-packages/django/core/urlresolvers.py", line 600, in is_valid_path
    resolve(path, urlconf)
  File "/Library/Python/2.7/site-packages/django/core/urlresolvers.py", line 480, in resolve
    return get_resolver(urlconf).resolve(path)
  File "/Library/Python/2.7/site-packages/django/core/urlresolvers.py", line 337, in resolve
    for pattern in self.url_patterns:
  File "/Library/Python/2.7/site-packages/django/core/urlresolvers.py", line 365, in url_patterns
    patterns = getattr(self.urlconf_module, "urlpatterns", self.urlconf_module)
  File "/Library/Python/2.7/site-packages/django/core/urlresolvers.py", line 360, in urlconf_module
    self._urlconf_module = import_module(self.urlconf_name)
  File "/Library/Python/2.7/site-packages/django/utils/importlib.py", line 40, in import_module
    __import__(name)
  File "/Users/prateek/sjsu/sos/sos/urls.py", line 4, in <module>
    from sos_app.views import UserViewSet, ContactsViewSet, IncidentsReportedViewSet,\
  File "/Users/prateek/sjsu/sos/sos_app/views.py", line 5, in <module>
    from sos_app.models import Contacts, Mobile_Device, Incidents_Reported,\
ImportError: cannot import name IncidentsReportedSerializer
[05/Oct/2014 08:48:43] INFO [sos_app.views:21] about to test
[05/Oct/2014 08:48:43] INFO [sos_app.views:27] about to test
[05/Oct/2014 08:48:43] INFO [sos_app.views:33] about to test
[05/Oct/2014 08:48:43] INFO [sos_app.views:39] about to test
[05/Oct/2014 08:49:01] INFO [sos_app.views:21] about to test
[05/Oct/2014 08:49:01] INFO [sos_app.views:27] about to test
[05/Oct/2014 08:49:01] INFO [sos_app.views:33] about to test
[05/Oct/2014 08:49:01] INFO [sos_app.views:39] about to test
[05/Oct/2014 08:52:46] INFO [sos_app.permissions:14] Mobile_Device object
[05/Oct/2014 08:52:46] INFO [sos_app.permissions:15] admin
[05/Oct/2014 08:52:46] INFO [sos_app.permissions:14] Mobile_Device object
[05/Oct/2014 08:52:46] INFO [sos_app.permissions:15] admin
[05/Oct/2014 08:52:46] INFO [sos_app.permissions:14] Mobile_Device object
[05/Oct/2014 08:52:46] INFO [sos_app.permissions:15] admin
[05/Oct/2014 08:52:54] INFO [sos_app.permissions:14] Mobile_Device object
[05/Oct/2014 08:52:54] INFO [sos_app.permissions:15] admin
[05/Oct/2014 08:52:54] INFO [sos_app.permissions:14] Mobile_Device object
[05/Oct/2014 08:52:54] INFO [sos_app.permissions:15] admin
[05/Oct/2014 08:52:54] INFO [sos_app.permissions:14] Mobile_Device object
[05/Oct/2014 08:52:54] INFO [sos_app.permissions:15] admin
[05/Oct/2014 08:52:54] INFO [sos_app.permissions:14] Mobile_Device object
[05/Oct/2014 08:52:54] INFO [sos_app.permissions:15] admin
[05/Oct/2014 08:52:54] INFO [sos_app.permissions:14] Mobile_Device object
[05/Oct/2014 08:52:54] INFO [sos_app.permissions:15] admin
[05/Oct/2014 08:52:54] INFO [sos_app.permissions:14] Mobile_Device object
[05/Oct/2014 08:52:54] INFO [sos_app.permissions:15] admin
[05/Oct/2014 08:52:57] INFO [sos_app.permissions:14] Mobile_Device object
[05/Oct/2014 08:52:57] INFO [sos_app.permissions:15] AnonymousUser
[05/Oct/2014 08:53:02] INFO [sos_app.permissions:14] Mobile_Device object
[05/Oct/2014 08:53:02] INFO [sos_app.permissions:15] prateek
[05/Oct/2014 08:54:32] INFO [sos_app.permissions:14] User_Location_Track object
[05/Oct/2014 08:54:32] INFO [sos_app.permissions:15] prateek
[05/Oct/2014 08:54:32] INFO [sos_app.permissions:14] User_Location_Track object
[05/Oct/2014 08:54:32] INFO [sos_app.permissions:15] prateek
[05/Oct/2014 08:54:32] INFO [sos_app.permissions:14] User_Location_Track object
[05/Oct/2014 08:54:32] INFO [sos_app.permissions:15] prateek
[05/Oct/2014 08:54:42] INFO [sos_app.permissions:14] User_Location_Track object
[05/Oct/2014 08:54:42] INFO [sos_app.permissions:15] prateek
[05/Oct/2014 08:54:42] INFO [sos_app.permissions:14] User_Location_Track object
[05/Oct/2014 08:54:42] INFO [sos_app.permissions:15] prateek
[05/Oct/2014 08:54:42] INFO [sos_app.permissions:14] User_Location_Track object
[05/Oct/2014 08:54:42] INFO [sos_app.permissions:15] prateek
[05/Oct/2014 08:54:42] INFO [sos_app.permissions:14] User_Location_Track object
[05/Oct/2014 08:54:42] INFO [sos_app.permissions:15] prateek
[05/Oct/2014 08:54:42] INFO [sos_app.permissions:14] User_Location_Track object
[05/Oct/2014 08:54:42] INFO [sos_app.permissions:15] prateek
[05/Oct/2014 08:54:42] INFO [sos_app.permissions:14] User_Location_Track object
[05/Oct/2014 08:54:42] INFO [sos_app.permissions:15] prateek
[05/Oct/2014 08:59:51] INFO [sos_app.views:23] about to test
[05/Oct/2014 08:59:51] INFO [sos_app.views:31] about to test
[05/Oct/2014 08:59:51] INFO [sos_app.views:39] about to test
[05/Oct/2014 08:59:51] INFO [sos_app.views:47] about to test
[05/Oct/2014 09:00:07] INFO [sos_app.permissions:14] User_Location_Track object
[05/Oct/2014 09:00:07] INFO [sos_app.permissions:15] prateek
[05/Oct/2014 09:00:07] INFO [sos_app.permissions:14] User_Location_Track object
[05/Oct/2014 09:00:07] INFO [sos_app.permissions:15] prateek
[05/Oct/2014 09:00:07] INFO [sos_app.permissions:14] User_Location_Track object
[05/Oct/2014 09:00:07] INFO [sos_app.permissions:15] prateek
[05/Oct/2014 09:05:12] INFO [sos_app.views:23] about to test
[05/Oct/2014 09:05:12] INFO [sos_app.views:31] about to test
[05/Oct/2014 09:05:12] INFO [sos_app.views:39] about to test
[05/Oct/2014 09:05:12] INFO [sos_app.views:47] about to test
[05/Oct/2014 09:05:39] INFO [sos_app.permissions:14] Contacts object
[05/Oct/2014 09:05:39] INFO [sos_app.permissions:15] prateek
[05/Oct/2014 09:05:39] INFO [sos_app.permissions:14] Contacts object
[05/Oct/2014 09:05:39] INFO [sos_app.permissions:15] prateek
[05/Oct/2014 09:05:39] INFO [sos_app.permissions:14] Contacts object
[05/Oct/2014 09:05:39] INFO [sos_app.permissions:15] prateek
[05/Oct/2014 09:05:50] INFO [sos_app.permissions:14] Contacts object
[05/Oct/2014 09:05:50] INFO [sos_app.permissions:15] prateek
[05/Oct/2014 09:05:50] INFO [sos_app.permissions:14] Contacts object
[05/Oct/2014 09:05:50] INFO [sos_app.permissions:15] prateek
[05/Oct/2014 09:05:50] INFO [sos_app.permissions:14] Contacts object
[05/Oct/2014 09:05:50] INFO [sos_app.permissions:15] prateek
[05/Oct/2014 09:05:50] INFO [sos_app.permissions:14] Contacts object
[05/Oct/2014 09:05:50] INFO [sos_app.permissions:15] prateek
[05/Oct/2014 09:05:50] INFO [sos_app.permissions:14] Contacts object
[05/Oct/2014 09:05:50] INFO [sos_app.permissions:15] prateek
[05/Oct/2014 09:05:50] INFO [sos_app.permissions:14] Contacts object
[05/Oct/2014 09:05:50] INFO [sos_app.permissions:15] prateek
[05/Oct/2014 09:05:59] INFO [sos_app.permissions:14] Contacts object
[05/Oct/2014 09:05:59] INFO [sos_app.permissions:15] AnonymousUser
[05/Oct/2014 09:06:03] INFO [sos_app.permissions:14] Contacts object
[05/Oct/2014 09:06:03] INFO [sos_app.permissions:15] admin
[05/Oct/2014 09:13:04] INFO [sos_app.permissions:14] Contacts object
[05/Oct/2014 09:13:04] INFO [sos_app.permissions:15] admin
[06/Oct/2014 00:00:23] INFO [sos_app.permissions:14] Contacts object
[06/Oct/2014 00:00:23] INFO [sos_app.permissions:15] admin
[06/Oct/2014 00:01:20] INFO [sos_app.views:23] about to test
[06/Oct/2014 00:01:20] INFO [sos_app.views:31] about to test
[06/Oct/2014 00:01:20] INFO [sos_app.views:39] about to test
[06/Oct/2014 00:01:20] INFO [sos_app.views:47] about to test
[06/Oct/2014 00:01:20] INFO [sos_app.permissions:14] Contacts object
[06/Oct/2014 00:01:20] INFO [sos_app.permissions:15] admin
[06/Oct/2014 00:01:56] INFO [sos_app.views:23] about to test
[06/Oct/2014 00:01:56] INFO [sos_app.views:31] about to test
[06/Oct/2014 00:01:56] INFO [sos_app.views:39] about to test
[06/Oct/2014 00:01:56] INFO [sos_app.views:47] about to test
[06/Oct/2014 00:05:27] ERROR [django.request:224] Internal Server Error: /contacts/
Traceback (most recent call last):
  File "/Library/Python/2.7/site-packages/django/core/handlers/base.py", line 99, in get_response
    resolver_match = resolver.resolve(request.path_info)
  File "/Library/Python/2.7/site-packages/django/core/urlresolvers.py", line 337, in resolve
    for pattern in self.url_patterns:
  File "/Library/Python/2.7/site-packages/django/core/urlresolvers.py", line 365, in url_patterns
    patterns = getattr(self.urlconf_module, "urlpatterns", self.urlconf_module)
  File "/Library/Python/2.7/site-packages/django/core/urlresolvers.py", line 360, in urlconf_module
    self._urlconf_module = import_module(self.urlconf_name)
  File "/Library/Python/2.7/site-packages/django/utils/importlib.py", line 40, in import_module
    __import__(name)
  File "/Users/prateek/sjsu/sos/sos/urls.py", line 4, in <module>
    from sos_app.views import UserViewSet, ContactsViewSet, IncidentsReportedViewSet,\
  File "/Users/prateek/sjsu/sos/sos_app/views.py", line 20, in <module>
    class ContactsViewSet(viewsets.ModelViewSet):
  File "/Users/prateek/sjsu/sos/sos_app/views.py", line 21, in ContactsViewSet
    queryset = Contacts.objects.filter(owner==request.user)
NameError: name 'owner' is not defined
[06/Oct/2014 00:09:07] ERROR [django.request:224] Internal Server Error: /contacts/
Traceback (most recent call last):
  File "/Library/Python/2.7/site-packages/django/core/handlers/base.py", line 99, in get_response
    resolver_match = resolver.resolve(request.path_info)
  File "/Library/Python/2.7/site-packages/django/core/urlresolvers.py", line 337, in resolve
    for pattern in self.url_patterns:
  File "/Library/Python/2.7/site-packages/django/core/urlresolvers.py", line 365, in url_patterns
    patterns = getattr(self.urlconf_module, "urlpatterns", self.urlconf_module)
  File "/Library/Python/2.7/site-packages/django/core/urlresolvers.py", line 360, in urlconf_module
    self._urlconf_module = import_module(self.urlconf_name)
  File "/Library/Python/2.7/site-packages/django/utils/importlib.py", line 40, in import_module
    __import__(name)
  File "/Users/prateek/sjsu/sos/sos/urls.py", line 4, in <module>
    from sos_app.views import UserViewSet, ContactsViewSet, IncidentsReportedViewSet,\
  File "/Users/prateek/sjsu/sos/sos_app/views.py", line 19, in <module>
    class ContactsViewSet(viewsets.ModelViewSet):
  File "/Users/prateek/sjsu/sos/sos_app/views.py", line 20, in ContactsViewSet
    queryset = Contacts.objects.filter(owner=self.request.user)
NameError: name 'self' is not defined
[06/Oct/2014 00:12:49] INFO [sos_app.views:22] about to test
[06/Oct/2014 00:12:49] INFO [sos_app.views:33] about to test
[06/Oct/2014 00:12:49] INFO [sos_app.views:41] about to test
[06/Oct/2014 00:12:49] INFO [sos_app.views:49] about to test
[06/Oct/2014 00:18:37] INFO [sos_app.views:22] about to test
[06/Oct/2014 00:18:37] INFO [sos_app.views:33] about to test
[06/Oct/2014 00:18:37] INFO [sos_app.views:41] about to test
[06/Oct/2014 00:18:37] INFO [sos_app.views:49] about to test
[06/Oct/2014 00:18:41] ERROR [django.request:224] Internal Server Error: /contacts/
Traceback (most recent call last):
  File "/Library/Python/2.7/site-packages/django/core/handlers/base.py", line 112, in get_response
    response = wrapped_callback(request, *callback_args, **callback_kwargs)
  File "/Library/Python/2.7/site-packages/django/views/decorators/csrf.py", line 57, in wrapped_view
    return view_func(*args, **kwargs)
  File "/Library/Python/2.7/site-packages/rest_framework/viewsets.py", line 79, in view
    return self.dispatch(request, *args, **kwargs)
  File "/Library/Python/2.7/site-packages/rest_framework/views.py", line 403, in dispatch
    response = self.handle_exception(exc)
  File "/Library/Python/2.7/site-packages/rest_framework/views.py", line 400, in dispatch
    response = handler(request, *args, **kwargs)
  File "/Library/Python/2.7/site-packages/rest_framework/mixins.py", line 76, in list
    self.object_list = self.filter_queryset(self.get_queryset())
  File "/Users/prateek/sjsu/sos/sos_app/views.py", line 28, in get_queryset
    return Contacts.objects.filter(owner=self.request.user)
  File "/Library/Python/2.7/site-packages/django/db/models/manager.py", line 163, in filter
    return self.get_queryset().filter(*args, **kwargs)
  File "/Library/Python/2.7/site-packages/django/db/models/query.py", line 593, in filter
    return self._filter_or_exclude(False, *args, **kwargs)
  File "/Library/Python/2.7/site-packages/django/db/models/query.py", line 611, in _filter_or_exclude
    clone.query.add_q(Q(*args, **kwargs))
  File "/Library/Python/2.7/site-packages/django/db/models/sql/query.py", line 1204, in add_q
    clause = self._add_q(where_part, used_aliases)
  File "/Library/Python/2.7/site-packages/django/db/models/sql/query.py", line 1240, in _add_q
    current_negated=current_negated)
  File "/Library/Python/2.7/site-packages/django/db/models/sql/query.py", line 1128, in build_filter
    lookup_type, value)
  File "/Library/Python/2.7/site-packages/django/db/models/fields/related.py", line 1107, in get_lookup_constraint
    value[index]), AND)
  File "/Library/Python/2.7/site-packages/django/utils/tree.py", line 104, in add
    data = self._prepare_data(data)
  File "/Library/Python/2.7/site-packages/django/db/models/sql/where.py", line 79, in _prepare_data
    value = obj.prepare(lookup_type, value)
  File "/Library/Python/2.7/site-packages/django/db/models/sql/where.py", line 352, in prepare
    return self.field.get_prep_lookup(lookup_type, value)
  File "/Library/Python/2.7/site-packages/django/db/models/fields/__init__.py", line 369, in get_prep_lookup
    return self.get_prep_value(value)
  File "/Library/Python/2.7/site-packages/django/db/models/fields/__init__.py", line 613, in get_prep_value
    return int(value)
TypeError: int() argument must be a string or a number, not 'AnonymousUser'
[06/Oct/2014 00:18:42] ERROR [django.request:224] Internal Server Error: /contacts/
Traceback (most recent call last):
  File "/Library/Python/2.7/site-packages/django/core/handlers/base.py", line 112, in get_response
    response = wrapped_callback(request, *callback_args, **callback_kwargs)
  File "/Library/Python/2.7/site-packages/django/views/decorators/csrf.py", line 57, in wrapped_view
    return view_func(*args, **kwargs)
  File "/Library/Python/2.7/site-packages/rest_framework/viewsets.py", line 79, in view
    return self.dispatch(request, *args, **kwargs)
  File "/Library/Python/2.7/site-packages/rest_framework/views.py", line 403, in dispatch
    response = self.handle_exception(exc)
  File "/Library/Python/2.7/site-packages/rest_framework/views.py", line 400, in dispatch
    response = handler(request, *args, **kwargs)
  File "/Library/Python/2.7/site-packages/rest_framework/mixins.py", line 76, in list
    self.object_list = self.filter_queryset(self.get_queryset())
  File "/Users/prateek/sjsu/sos/sos_app/views.py", line 28, in get_queryset
    return Contacts.objects.filter(owner=self.request.user)
  File "/Library/Python/2.7/site-packages/django/db/models/manager.py", line 163, in filter
    return self.get_queryset().filter(*args, **kwargs)
  File "/Library/Python/2.7/site-packages/django/db/models/query.py", line 593, in filter
    return self._filter_or_exclude(False, *args, **kwargs)
  File "/Library/Python/2.7/site-packages/django/db/models/query.py", line 611, in _filter_or_exclude
    clone.query.add_q(Q(*args, **kwargs))
  File "/Library/Python/2.7/site-packages/django/db/models/sql/query.py", line 1204, in add_q
    clause = self._add_q(where_part, used_aliases)
  File "/Library/Python/2.7/site-packages/django/db/models/sql/query.py", line 1240, in _add_q
    current_negated=current_negated)
  File "/Library/Python/2.7/site-packages/django/db/models/sql/query.py", line 1128, in build_filter
    lookup_type, value)
  File "/Library/Python/2.7/site-packages/django/db/models/fields/related.py", line 1107, in get_lookup_constraint
    value[index]), AND)
  File "/Library/Python/2.7/site-packages/django/utils/tree.py", line 104, in add
    data = self._prepare_data(data)
  File "/Library/Python/2.7/site-packages/django/db/models/sql/where.py", line 79, in _prepare_data
    value = obj.prepare(lookup_type, value)
  File "/Library/Python/2.7/site-packages/django/db/models/sql/where.py", line 352, in prepare
    return self.field.get_prep_lookup(lookup_type, value)
  File "/Library/Python/2.7/site-packages/django/db/models/fields/__init__.py", line 369, in get_prep_lookup
    return self.get_prep_value(value)
  File "/Library/Python/2.7/site-packages/django/db/models/fields/__init__.py", line 613, in get_prep_value
    return int(value)
TypeError: int() argument must be a string or a number, not 'AnonymousUser'
[06/Oct/2014 00:18:43] ERROR [django.request:224] Internal Server Error: /contacts/
Traceback (most recent call last):
  File "/Library/Python/2.7/site-packages/django/core/handlers/base.py", line 112, in get_response
    response = wrapped_callback(request, *callback_args, **callback_kwargs)
  File "/Library/Python/2.7/site-packages/django/views/decorators/csrf.py", line 57, in wrapped_view
    return view_func(*args, **kwargs)
  File "/Library/Python/2.7/site-packages/rest_framework/viewsets.py", line 79, in view
    return self.dispatch(request, *args, **kwargs)
  File "/Library/Python/2.7/site-packages/rest_framework/views.py", line 403, in dispatch
    response = self.handle_exception(exc)
  File "/Library/Python/2.7/site-packages/rest_framework/views.py", line 400, in dispatch
    response = handler(request, *args, **kwargs)
  File "/Library/Python/2.7/site-packages/rest_framework/mixins.py", line 76, in list
    self.object_list = self.filter_queryset(self.get_queryset())
  File "/Users/prateek/sjsu/sos/sos_app/views.py", line 28, in get_queryset
    return Contacts.objects.filter(owner=self.request.user)
  File "/Library/Python/2.7/site-packages/django/db/models/manager.py", line 163, in filter
    return self.get_queryset().filter(*args, **kwargs)
  File "/Library/Python/2.7/site-packages/django/db/models/query.py", line 593, in filter
    return self._filter_or_exclude(False, *args, **kwargs)
  File "/Library/Python/2.7/site-packages/django/db/models/query.py", line 611, in _filter_or_exclude
    clone.query.add_q(Q(*args, **kwargs))
  File "/Library/Python/2.7/site-packages/django/db/models/sql/query.py", line 1204, in add_q
    clause = self._add_q(where_part, used_aliases)
  File "/Library/Python/2.7/site-packages/django/db/models/sql/query.py", line 1240, in _add_q
    current_negated=current_negated)
  File "/Library/Python/2.7/site-packages/django/db/models/sql/query.py", line 1128, in build_filter
    lookup_type, value)
  File "/Library/Python/2.7/site-packages/django/db/models/fields/related.py", line 1107, in get_lookup_constraint
    value[index]), AND)
  File "/Library/Python/2.7/site-packages/django/utils/tree.py", line 104, in add
    data = self._prepare_data(data)
  File "/Library/Python/2.7/site-packages/django/db/models/sql/where.py", line 79, in _prepare_data
    value = obj.prepare(lookup_type, value)
  File "/Library/Python/2.7/site-packages/django/db/models/sql/where.py", line 352, in prepare
    return self.field.get_prep_lookup(lookup_type, value)
  File "/Library/Python/2.7/site-packages/django/db/models/fields/__init__.py", line 369, in get_prep_lookup
    return self.get_prep_value(value)
  File "/Library/Python/2.7/site-packages/django/db/models/fields/__init__.py", line 613, in get_prep_value
    return int(value)
TypeError: int() argument must be a string or a number, not 'AnonymousUser'
[06/Oct/2014 00:18:44] ERROR [django.request:224] Internal Server Error: /contacts/
Traceback (most recent call last):
  File "/Library/Python/2.7/site-packages/django/core/handlers/base.py", line 112, in get_response
    response = wrapped_callback(request, *callback_args, **callback_kwargs)
  File "/Library/Python/2.7/site-packages/django/views/decorators/csrf.py", line 57, in wrapped_view
    return view_func(*args, **kwargs)
  File "/Library/Python/2.7/site-packages/rest_framework/viewsets.py", line 79, in view
    return self.dispatch(request, *args, **kwargs)
  File "/Library/Python/2.7/site-packages/rest_framework/views.py", line 403, in dispatch
    response = self.handle_exception(exc)
  File "/Library/Python/2.7/site-packages/rest_framework/views.py", line 400, in dispatch
    response = handler(request, *args, **kwargs)
  File "/Library/Python/2.7/site-packages/rest_framework/mixins.py", line 76, in list
    self.object_list = self.filter_queryset(self.get_queryset())
  File "/Users/prateek/sjsu/sos/sos_app/views.py", line 28, in get_queryset
    return Contacts.objects.filter(owner=self.request.user)
  File "/Library/Python/2.7/site-packages/django/db/models/manager.py", line 163, in filter
    return self.get_queryset().filter(*args, **kwargs)
  File "/Library/Python/2.7/site-packages/django/db/models/query.py", line 593, in filter
    return self._filter_or_exclude(False, *args, **kwargs)
  File "/Library/Python/2.7/site-packages/django/db/models/query.py", line 611, in _filter_or_exclude
    clone.query.add_q(Q(*args, **kwargs))
  File "/Library/Python/2.7/site-packages/django/db/models/sql/query.py", line 1204, in add_q
    clause = self._add_q(where_part, used_aliases)
  File "/Library/Python/2.7/site-packages/django/db/models/sql/query.py", line 1240, in _add_q
    current_negated=current_negated)
  File "/Library/Python/2.7/site-packages/django/db/models/sql/query.py", line 1128, in build_filter
    lookup_type, value)
  File "/Library/Python/2.7/site-packages/django/db/models/fields/related.py", line 1107, in get_lookup_constraint
    value[index]), AND)
  File "/Library/Python/2.7/site-packages/django/utils/tree.py", line 104, in add
    data = self._prepare_data(data)
  File "/Library/Python/2.7/site-packages/django/db/models/sql/where.py", line 79, in _prepare_data
    value = obj.prepare(lookup_type, value)
  File "/Library/Python/2.7/site-packages/django/db/models/sql/where.py", line 352, in prepare
    return self.field.get_prep_lookup(lookup_type, value)
  File "/Library/Python/2.7/site-packages/django/db/models/fields/__init__.py", line 369, in get_prep_lookup
    return self.get_prep_value(value)
  File "/Library/Python/2.7/site-packages/django/db/models/fields/__init__.py", line 613, in get_prep_value
    return int(value)
TypeError: int() argument must be a string or a number, not 'AnonymousUser'
[06/Oct/2014 00:18:44] ERROR [django.request:224] Internal Server Error: /contacts/
Traceback (most recent call last):
  File "/Library/Python/2.7/site-packages/django/core/handlers/base.py", line 112, in get_response
    response = wrapped_callback(request, *callback_args, **callback_kwargs)
  File "/Library/Python/2.7/site-packages/django/views/decorators/csrf.py", line 57, in wrapped_view
    return view_func(*args, **kwargs)
  File "/Library/Python/2.7/site-packages/rest_framework/viewsets.py", line 79, in view
    return self.dispatch(request, *args, **kwargs)
  File "/Library/Python/2.7/site-packages/rest_framework/views.py", line 403, in dispatch
    response = self.handle_exception(exc)
  File "/Library/Python/2.7/site-packages/rest_framework/views.py", line 400, in dispatch
    response = handler(request, *args, **kwargs)
  File "/Library/Python/2.7/site-packages/rest_framework/mixins.py", line 76, in list
    self.object_list = self.filter_queryset(self.get_queryset())
  File "/Users/prateek/sjsu/sos/sos_app/views.py", line 28, in get_queryset
    return Contacts.objects.filter(owner=self.request.user)
  File "/Library/Python/2.7/site-packages/django/db/models/manager.py", line 163, in filter
    return self.get_queryset().filter(*args, **kwargs)
  File "/Library/Python/2.7/site-packages/django/db/models/query.py", line 593, in filter
    return self._filter_or_exclude(False, *args, **kwargs)
  File "/Library/Python/2.7/site-packages/django/db/models/query.py", line 611, in _filter_or_exclude
    clone.query.add_q(Q(*args, **kwargs))
  File "/Library/Python/2.7/site-packages/django/db/models/sql/query.py", line 1204, in add_q
    clause = self._add_q(where_part, used_aliases)
  File "/Library/Python/2.7/site-packages/django/db/models/sql/query.py", line 1240, in _add_q
    current_negated=current_negated)
  File "/Library/Python/2.7/site-packages/django/db/models/sql/query.py", line 1128, in build_filter
    lookup_type, value)
  File "/Library/Python/2.7/site-packages/django/db/models/fields/related.py", line 1107, in get_lookup_constraint
    value[index]), AND)
  File "/Library/Python/2.7/site-packages/django/utils/tree.py", line 104, in add
    data = self._prepare_data(data)
  File "/Library/Python/2.7/site-packages/django/db/models/sql/where.py", line 79, in _prepare_data
    value = obj.prepare(lookup_type, value)
  File "/Library/Python/2.7/site-packages/django/db/models/sql/where.py", line 352, in prepare
    return self.field.get_prep_lookup(lookup_type, value)
  File "/Library/Python/2.7/site-packages/django/db/models/fields/__init__.py", line 369, in get_prep_lookup
    return self.get_prep_value(value)
  File "/Library/Python/2.7/site-packages/django/db/models/fields/__init__.py", line 613, in get_prep_value
    return int(value)
TypeError: int() argument must be a string or a number, not 'AnonymousUser'
[06/Oct/2014 00:19:25] ERROR [django.request:224] Internal Server Error: /contacts/
Traceback (most recent call last):
  File "/Library/Python/2.7/site-packages/django/core/handlers/base.py", line 99, in get_response
    resolver_match = resolver.resolve(request.path_info)
  File "/Library/Python/2.7/site-packages/django/core/urlresolvers.py", line 337, in resolve
    for pattern in self.url_patterns:
  File "/Library/Python/2.7/site-packages/django/core/urlresolvers.py", line 365, in url_patterns
    patterns = getattr(self.urlconf_module, "urlpatterns", self.urlconf_module)
  File "/Library/Python/2.7/site-packages/django/core/urlresolvers.py", line 360, in urlconf_module
    self._urlconf_module = import_module(self.urlconf_name)
  File "/Library/Python/2.7/site-packages/django/utils/importlib.py", line 40, in import_module
    __import__(name)
  File "/Users/prateek/sjsu/sos/sos/urls.py", line 4, in <module>
    from sos_app.views import UserViewSet, ContactsViewSet, IncidentsReportedViewSet,\
  File "/Users/prateek/sjsu/sos/sos_app/views.py", line 30
    else
       ^
SyntaxError: invalid syntax
[06/Oct/2014 00:19:31] INFO [sos_app.views:22] about to test
[06/Oct/2014 00:19:31] INFO [sos_app.views:36] about to test
[06/Oct/2014 00:19:31] INFO [sos_app.views:44] about to test
[06/Oct/2014 00:19:31] INFO [sos_app.views:52] about to test
[06/Oct/2014 00:19:31] ERROR [django.request:224] Internal Server Error: /contacts/
Traceback (most recent call last):
  File "/Library/Python/2.7/site-packages/django/core/handlers/base.py", line 112, in get_response
    response = wrapped_callback(request, *callback_args, **callback_kwargs)
  File "/Library/Python/2.7/site-packages/django/views/decorators/csrf.py", line 57, in wrapped_view
    return view_func(*args, **kwargs)
  File "/Library/Python/2.7/site-packages/rest_framework/viewsets.py", line 79, in view
    return self.dispatch(request, *args, **kwargs)
  File "/Library/Python/2.7/site-packages/rest_framework/views.py", line 403, in dispatch
    response = self.handle_exception(exc)
  File "/Library/Python/2.7/site-packages/rest_framework/views.py", line 400, in dispatch
    response = handler(request, *args, **kwargs)
  File "/Library/Python/2.7/site-packages/rest_framework/mixins.py", line 76, in list
    self.object_list = self.filter_queryset(self.get_queryset())
  File "/Users/prateek/sjsu/sos/sos_app/views.py", line 29, in get_queryset
    return Contacts.objects.filter(owner=self.request.user)
  File "/Library/Python/2.7/site-packages/django/db/models/manager.py", line 163, in filter
    return self.get_queryset().filter(*args, **kwargs)
  File "/Library/Python/2.7/site-packages/django/db/models/query.py", line 593, in filter
    return self._filter_or_exclude(False, *args, **kwargs)
  File "/Library/Python/2.7/site-packages/django/db/models/query.py", line 611, in _filter_or_exclude
    clone.query.add_q(Q(*args, **kwargs))
  File "/Library/Python/2.7/site-packages/django/db/models/sql/query.py", line 1204, in add_q
    clause = self._add_q(where_part, used_aliases)
  File "/Library/Python/2.7/site-packages/django/db/models/sql/query.py", line 1240, in _add_q
    current_negated=current_negated)
  File "/Library/Python/2.7/site-packages/django/db/models/sql/query.py", line 1128, in build_filter
    lookup_type, value)
  File "/Library/Python/2.7/site-packages/django/db/models/fields/related.py", line 1107, in get_lookup_constraint
    value[index]), AND)
  File "/Library/Python/2.7/site-packages/django/utils/tree.py", line 104, in add
    data = self._prepare_data(data)
  File "/Library/Python/2.7/site-packages/django/db/models/sql/where.py", line 79, in _prepare_data
    value = obj.prepare(lookup_type, value)
  File "/Library/Python/2.7/site-packages/django/db/models/sql/where.py", line 352, in prepare
    return self.field.get_prep_lookup(lookup_type, value)
  File "/Library/Python/2.7/site-packages/django/db/models/fields/__init__.py", line 369, in get_prep_lookup
    return self.get_prep_value(value)
  File "/Library/Python/2.7/site-packages/django/db/models/fields/__init__.py", line 613, in get_prep_value
    return int(value)
TypeError: int() argument must be a string or a number, not 'AnonymousUser'
[06/Oct/2014 00:19:54] INFO [sos_app.views:22] about to test
[06/Oct/2014 00:19:54] INFO [sos_app.views:36] about to test
[06/Oct/2014 00:19:54] INFO [sos_app.views:44] about to test
[06/Oct/2014 00:19:54] INFO [sos_app.views:52] about to test
[06/Oct/2014 00:19:54] ERROR [django.request:224] Internal Server Error: /contacts/
Traceback (most recent call last):
  File "/Library/Python/2.7/site-packages/django/core/handlers/base.py", line 112, in get_response
    response = wrapped_callback(request, *callback_args, **callback_kwargs)
  File "/Library/Python/2.7/site-packages/django/views/decorators/csrf.py", line 57, in wrapped_view
    return view_func(*args, **kwargs)
  File "/Library/Python/2.7/site-packages/rest_framework/viewsets.py", line 79, in view
    return self.dispatch(request, *args, **kwargs)
  File "/Library/Python/2.7/site-packages/rest_framework/views.py", line 403, in dispatch
    response = self.handle_exception(exc)
  File "/Library/Python/2.7/site-packages/rest_framework/views.py", line 400, in dispatch
    response = handler(request, *args, **kwargs)
  File "/Library/Python/2.7/site-packages/rest_framework/mixins.py", line 76, in list
    self.object_list = self.filter_queryset(self.get_queryset())
  File "/Users/prateek/sjsu/sos/sos_app/views.py", line 29, in get_queryset
    return Contacts.objects.filter(owner=self.request.user)
  File "/Library/Python/2.7/site-packages/django/db/models/manager.py", line 163, in filter
    return self.get_queryset().filter(*args, **kwargs)
  File "/Library/Python/2.7/site-packages/django/db/models/query.py", line 593, in filter
    return self._filter_or_exclude(False, *args, **kwargs)
  File "/Library/Python/2.7/site-packages/django/db/models/query.py", line 611, in _filter_or_exclude
    clone.query.add_q(Q(*args, **kwargs))
  File "/Library/Python/2.7/site-packages/django/db/models/sql/query.py", line 1204, in add_q
    clause = self._add_q(where_part, used_aliases)
  File "/Library/Python/2.7/site-packages/django/db/models/sql/query.py", line 1240, in _add_q
    current_negated=current_negated)
  File "/Library/Python/2.7/site-packages/django/db/models/sql/query.py", line 1128, in build_filter
    lookup_type, value)
  File "/Library/Python/2.7/site-packages/django/db/models/fields/related.py", line 1107, in get_lookup_constraint
    value[index]), AND)
  File "/Library/Python/2.7/site-packages/django/utils/tree.py", line 104, in add
    data = self._prepare_data(data)
  File "/Library/Python/2.7/site-packages/django/db/models/sql/where.py", line 79, in _prepare_data
    value = obj.prepare(lookup_type, value)
  File "/Library/Python/2.7/site-packages/django/db/models/sql/where.py", line 352, in prepare
    return self.field.get_prep_lookup(lookup_type, value)
  File "/Library/Python/2.7/site-packages/django/db/models/fields/__init__.py", line 369, in get_prep_lookup
    return self.get_prep_value(value)
  File "/Library/Python/2.7/site-packages/django/db/models/fields/__init__.py", line 613, in get_prep_value
    return int(value)
TypeError: int() argument must be a string or a number, not 'AnonymousUser'
[06/Oct/2014 00:20:49] INFO [sos_app.views:22] about to test
[06/Oct/2014 00:20:49] INFO [sos_app.views:36] about to test
[06/Oct/2014 00:20:49] INFO [sos_app.views:44] about to test
[06/Oct/2014 00:20:49] INFO [sos_app.views:52] about to test
[06/Oct/2014 00:20:49] ERROR [django.request:224] Internal Server Error: /contacts/
Traceback (most recent call last):
  File "/Library/Python/2.7/site-packages/django/core/handlers/base.py", line 112, in get_response
    response = wrapped_callback(request, *callback_args, **callback_kwargs)
  File "/Library/Python/2.7/site-packages/django/views/decorators/csrf.py", line 57, in wrapped_view
    return view_func(*args, **kwargs)
  File "/Library/Python/2.7/site-packages/rest_framework/viewsets.py", line 79, in view
    return self.dispatch(request, *args, **kwargs)
  File "/Library/Python/2.7/site-packages/rest_framework/views.py", line 403, in dispatch
    response = self.handle_exception(exc)
  File "/Library/Python/2.7/site-packages/rest_framework/views.py", line 400, in dispatch
    response = handler(request, *args, **kwargs)
  File "/Library/Python/2.7/site-packages/rest_framework/mixins.py", line 76, in list
    self.object_list = self.filter_queryset(self.get_queryset())
  File "/Users/prateek/sjsu/sos/sos_app/views.py", line 29, in get_queryset
    return Contacts.objects.filter(owner=self.request.user)
  File "/Library/Python/2.7/site-packages/django/db/models/manager.py", line 163, in filter
    return self.get_queryset().filter(*args, **kwargs)
  File "/Library/Python/2.7/site-packages/django/db/models/query.py", line 593, in filter
    return self._filter_or_exclude(False, *args, **kwargs)
  File "/Library/Python/2.7/site-packages/django/db/models/query.py", line 611, in _filter_or_exclude
    clone.query.add_q(Q(*args, **kwargs))
  File "/Library/Python/2.7/site-packages/django/db/models/sql/query.py", line 1204, in add_q
    clause = self._add_q(where_part, used_aliases)
  File "/Library/Python/2.7/site-packages/django/db/models/sql/query.py", line 1240, in _add_q
    current_negated=current_negated)
  File "/Library/Python/2.7/site-packages/django/db/models/sql/query.py", line 1128, in build_filter
    lookup_type, value)
  File "/Library/Python/2.7/site-packages/django/db/models/fields/related.py", line 1107, in get_lookup_constraint
    value[index]), AND)
  File "/Library/Python/2.7/site-packages/django/utils/tree.py", line 104, in add
    data = self._prepare_data(data)
  File "/Library/Python/2.7/site-packages/django/db/models/sql/where.py", line 79, in _prepare_data
    value = obj.prepare(lookup_type, value)
  File "/Library/Python/2.7/site-packages/django/db/models/sql/where.py", line 352, in prepare
    return self.field.get_prep_lookup(lookup_type, value)
  File "/Library/Python/2.7/site-packages/django/db/models/fields/__init__.py", line 369, in get_prep_lookup
    return self.get_prep_value(value)
  File "/Library/Python/2.7/site-packages/django/db/models/fields/__init__.py", line 613, in get_prep_value
    return int(value)
TypeError: int() argument must be a string or a number, not 'AnonymousUser'
[06/Oct/2014 00:21:24] ERROR [django.request:224] Internal Server Error: /contacts/
Traceback (most recent call last):
  File "/Library/Python/2.7/site-packages/django/core/handlers/base.py", line 112, in get_response
    response = wrapped_callback(request, *callback_args, **callback_kwargs)
  File "/Library/Python/2.7/site-packages/django/views/decorators/csrf.py", line 57, in wrapped_view
    return view_func(*args, **kwargs)
  File "/Library/Python/2.7/site-packages/rest_framework/viewsets.py", line 79, in view
    return self.dispatch(request, *args, **kwargs)
  File "/Library/Python/2.7/site-packages/rest_framework/views.py", line 403, in dispatch
    response = self.handle_exception(exc)
  File "/Library/Python/2.7/site-packages/rest_framework/views.py", line 400, in dispatch
    response = handler(request, *args, **kwargs)
  File "/Library/Python/2.7/site-packages/rest_framework/mixins.py", line 76, in list
    self.object_list = self.filter_queryset(self.get_queryset())
  File "/Users/prateek/sjsu/sos/sos_app/views.py", line 29, in get_queryset
    return Contacts.objects.filter(owner=self.request.user)
  File "/Library/Python/2.7/site-packages/django/db/models/manager.py", line 163, in filter
    return self.get_queryset().filter(*args, **kwargs)
  File "/Library/Python/2.7/site-packages/django/db/models/query.py", line 593, in filter
    return self._filter_or_exclude(False, *args, **kwargs)
  File "/Library/Python/2.7/site-packages/django/db/models/query.py", line 611, in _filter_or_exclude
    clone.query.add_q(Q(*args, **kwargs))
  File "/Library/Python/2.7/site-packages/django/db/models/sql/query.py", line 1204, in add_q
    clause = self._add_q(where_part, used_aliases)
  File "/Library/Python/2.7/site-packages/django/db/models/sql/query.py", line 1240, in _add_q
    current_negated=current_negated)
  File "/Library/Python/2.7/site-packages/django/db/models/sql/query.py", line 1128, in build_filter
    lookup_type, value)
  File "/Library/Python/2.7/site-packages/django/db/models/fields/related.py", line 1107, in get_lookup_constraint
    value[index]), AND)
  File "/Library/Python/2.7/site-packages/django/utils/tree.py", line 104, in add
    data = self._prepare_data(data)
  File "/Library/Python/2.7/site-packages/django/db/models/sql/where.py", line 79, in _prepare_data
    value = obj.prepare(lookup_type, value)
  File "/Library/Python/2.7/site-packages/django/db/models/sql/where.py", line 352, in prepare
    return self.field.get_prep_lookup(lookup_type, value)
  File "/Library/Python/2.7/site-packages/django/db/models/fields/__init__.py", line 369, in get_prep_lookup
    return self.get_prep_value(value)
  File "/Library/Python/2.7/site-packages/django/db/models/fields/__init__.py", line 613, in get_prep_value
    return int(value)
TypeError: int() argument must be a string or a number, not 'AnonymousUser'
[06/Oct/2014 00:21:48] INFO [sos_app.views:22] about to test
[06/Oct/2014 00:21:48] INFO [sos_app.views:36] about to test
[06/Oct/2014 00:21:48] INFO [sos_app.views:44] about to test
[06/Oct/2014 00:21:48] INFO [sos_app.views:52] about to test
[06/Oct/2014 00:21:48] ERROR [django.request:224] Internal Server Error: /contacts/
Traceback (most recent call last):
  File "/Library/Python/2.7/site-packages/django/core/handlers/base.py", line 112, in get_response
    response = wrapped_callback(request, *callback_args, **callback_kwargs)
  File "/Library/Python/2.7/site-packages/django/views/decorators/csrf.py", line 57, in wrapped_view
    return view_func(*args, **kwargs)
  File "/Library/Python/2.7/site-packages/rest_framework/viewsets.py", line 79, in view
    return self.dispatch(request, *args, **kwargs)
  File "/Library/Python/2.7/site-packages/rest_framework/views.py", line 403, in dispatch
    response = self.handle_exception(exc)
  File "/Library/Python/2.7/site-packages/rest_framework/views.py", line 400, in dispatch
    response = handler(request, *args, **kwargs)
  File "/Library/Python/2.7/site-packages/rest_framework/mixins.py", line 76, in list
    self.object_list = self.filter_queryset(self.get_queryset())
  File "/Users/prateek/sjsu/sos/sos_app/views.py", line 29, in get_queryset
    return Contacts.objects.filter(owner=self.request.user)
  File "/Library/Python/2.7/site-packages/django/db/models/manager.py", line 163, in filter
    return self.get_queryset().filter(*args, **kwargs)
  File "/Library/Python/2.7/site-packages/django/db/models/query.py", line 593, in filter
    return self._filter_or_exclude(False, *args, **kwargs)
  File "/Library/Python/2.7/site-packages/django/db/models/query.py", line 611, in _filter_or_exclude
    clone.query.add_q(Q(*args, **kwargs))
  File "/Library/Python/2.7/site-packages/django/db/models/sql/query.py", line 1204, in add_q
    clause = self._add_q(where_part, used_aliases)
  File "/Library/Python/2.7/site-packages/django/db/models/sql/query.py", line 1240, in _add_q
    current_negated=current_negated)
  File "/Library/Python/2.7/site-packages/django/db/models/sql/query.py", line 1128, in build_filter
    lookup_type, value)
  File "/Library/Python/2.7/site-packages/django/db/models/fields/related.py", line 1107, in get_lookup_constraint
    value[index]), AND)
  File "/Library/Python/2.7/site-packages/django/utils/tree.py", line 104, in add
    data = self._prepare_data(data)
  File "/Library/Python/2.7/site-packages/django/db/models/sql/where.py", line 79, in _prepare_data
    value = obj.prepare(lookup_type, value)
  File "/Library/Python/2.7/site-packages/django/db/models/sql/where.py", line 352, in prepare
    return self.field.get_prep_lookup(lookup_type, value)
  File "/Library/Python/2.7/site-packages/django/db/models/fields/__init__.py", line 369, in get_prep_lookup
    return self.get_prep_value(value)
  File "/Library/Python/2.7/site-packages/django/db/models/fields/__init__.py", line 613, in get_prep_value
    return int(value)
TypeError: int() argument must be a string or a number, not 'AnonymousUser'
[06/Oct/2014 00:22:47] INFO [sos_app.views:22] about to test
[06/Oct/2014 00:22:47] INFO [sos_app.views:39] about to test
[06/Oct/2014 00:22:47] INFO [sos_app.views:47] about to test
[06/Oct/2014 00:22:47] INFO [sos_app.views:55] about to test
[06/Oct/2014 00:22:47] INFO [sos_app.views:28] Alright, getting queryset
[06/Oct/2014 00:22:47] INFO [sos_app.views:30] Returning filtered queryset
[06/Oct/2014 00:22:47] ERROR [django.request:224] Internal Server Error: /contacts/
Traceback (most recent call last):
  File "/Library/Python/2.7/site-packages/django/core/handlers/base.py", line 112, in get_response
    response = wrapped_callback(request, *callback_args, **callback_kwargs)
  File "/Library/Python/2.7/site-packages/django/views/decorators/csrf.py", line 57, in wrapped_view
    return view_func(*args, **kwargs)
  File "/Library/Python/2.7/site-packages/rest_framework/viewsets.py", line 79, in view
    return self.dispatch(request, *args, **kwargs)
  File "/Library/Python/2.7/site-packages/rest_framework/views.py", line 403, in dispatch
    response = self.handle_exception(exc)
  File "/Library/Python/2.7/site-packages/rest_framework/views.py", line 400, in dispatch
    response = handler(request, *args, **kwargs)
  File "/Library/Python/2.7/site-packages/rest_framework/mixins.py", line 76, in list
    self.object_list = self.filter_queryset(self.get_queryset())
  File "/Users/prateek/sjsu/sos/sos_app/views.py", line 31, in get_queryset
    return Contacts.objects.filter(owner=self.request.user)
  File "/Library/Python/2.7/site-packages/django/db/models/manager.py", line 163, in filter
    return self.get_queryset().filter(*args, **kwargs)
  File "/Library/Python/2.7/site-packages/django/db/models/query.py", line 593, in filter
    return self._filter_or_exclude(False, *args, **kwargs)
  File "/Library/Python/2.7/site-packages/django/db/models/query.py", line 611, in _filter_or_exclude
    clone.query.add_q(Q(*args, **kwargs))
  File "/Library/Python/2.7/site-packages/django/db/models/sql/query.py", line 1204, in add_q
    clause = self._add_q(where_part, used_aliases)
  File "/Library/Python/2.7/site-packages/django/db/models/sql/query.py", line 1240, in _add_q
    current_negated=current_negated)
  File "/Library/Python/2.7/site-packages/django/db/models/sql/query.py", line 1128, in build_filter
    lookup_type, value)
  File "/Library/Python/2.7/site-packages/django/db/models/fields/related.py", line 1107, in get_lookup_constraint
    value[index]), AND)
  File "/Library/Python/2.7/site-packages/django/utils/tree.py", line 104, in add
    data = self._prepare_data(data)
  File "/Library/Python/2.7/site-packages/django/db/models/sql/where.py", line 79, in _prepare_data
    value = obj.prepare(lookup_type, value)
  File "/Library/Python/2.7/site-packages/django/db/models/sql/where.py", line 352, in prepare
    return self.field.get_prep_lookup(lookup_type, value)
  File "/Library/Python/2.7/site-packages/django/db/models/fields/__init__.py", line 369, in get_prep_lookup
    return self.get_prep_value(value)
  File "/Library/Python/2.7/site-packages/django/db/models/fields/__init__.py", line 613, in get_prep_value
    return int(value)
TypeError: int() argument must be a string or a number, not 'AnonymousUser'
[06/Oct/2014 00:23:19] INFO [sos_app.views:22] about to test
[06/Oct/2014 00:23:19] INFO [sos_app.views:39] about to test
[06/Oct/2014 00:23:19] INFO [sos_app.views:47] about to test
[06/Oct/2014 00:23:19] INFO [sos_app.views:55] about to test
[06/Oct/2014 00:23:19] ERROR [django.request:224] Internal Server Error: /contacts/
Traceback (most recent call last):
  File "/Library/Python/2.7/site-packages/django/core/handlers/base.py", line 112, in get_response
    response = wrapped_callback(request, *callback_args, **callback_kwargs)
  File "/Library/Python/2.7/site-packages/django/views/decorators/csrf.py", line 57, in wrapped_view
    return view_func(*args, **kwargs)
  File "/Library/Python/2.7/site-packages/rest_framework/viewsets.py", line 79, in view
    return self.dispatch(request, *args, **kwargs)
  File "/Library/Python/2.7/site-packages/rest_framework/views.py", line 403, in dispatch
    response = self.handle_exception(exc)
  File "/Library/Python/2.7/site-packages/rest_framework/views.py", line 400, in dispatch
    response = handler(request, *args, **kwargs)
  File "/Library/Python/2.7/site-packages/rest_framework/mixins.py", line 76, in list
    self.object_list = self.filter_queryset(self.get_queryset())
  File "/Users/prateek/sjsu/sos/sos_app/views.py", line 28, in get_queryset
    logger.info("Alright, getting queryset for - "+self.request.user)
TypeError: cannot concatenate 'str' and 'AnonymousUser' objects
[06/Oct/2014 00:23:36] INFO [sos_app.views:22] about to test
[06/Oct/2014 00:23:36] INFO [sos_app.views:39] about to test
[06/Oct/2014 00:23:36] INFO [sos_app.views:47] about to test
[06/Oct/2014 00:23:36] INFO [sos_app.views:55] about to test
[06/Oct/2014 00:23:36] INFO [sos_app.views:28] AnonymousUser
[06/Oct/2014 00:23:36] INFO [sos_app.views:30] Returning filtered queryset
[06/Oct/2014 00:23:36] ERROR [django.request:224] Internal Server Error: /contacts/
Traceback (most recent call last):
  File "/Library/Python/2.7/site-packages/django/core/handlers/base.py", line 112, in get_response
    response = wrapped_callback(request, *callback_args, **callback_kwargs)
  File "/Library/Python/2.7/site-packages/django/views/decorators/csrf.py", line 57, in wrapped_view
    return view_func(*args, **kwargs)
  File "/Library/Python/2.7/site-packages/rest_framework/viewsets.py", line 79, in view
    return self.dispatch(request, *args, **kwargs)
  File "/Library/Python/2.7/site-packages/rest_framework/views.py", line 403, in dispatch
    response = self.handle_exception(exc)
  File "/Library/Python/2.7/site-packages/rest_framework/views.py", line 400, in dispatch
    response = handler(request, *args, **kwargs)
  File "/Library/Python/2.7/site-packages/rest_framework/mixins.py", line 76, in list
    self.object_list = self.filter_queryset(self.get_queryset())
  File "/Users/prateek/sjsu/sos/sos_app/views.py", line 31, in get_queryset
    return Contacts.objects.filter(owner=self.request.user)
  File "/Library/Python/2.7/site-packages/django/db/models/manager.py", line 163, in filter
    return self.get_queryset().filter(*args, **kwargs)
  File "/Library/Python/2.7/site-packages/django/db/models/query.py", line 593, in filter
    return self._filter_or_exclude(False, *args, **kwargs)
  File "/Library/Python/2.7/site-packages/django/db/models/query.py", line 611, in _filter_or_exclude
    clone.query.add_q(Q(*args, **kwargs))
  File "/Library/Python/2.7/site-packages/django/db/models/sql/query.py", line 1204, in add_q
    clause = self._add_q(where_part, used_aliases)
  File "/Library/Python/2.7/site-packages/django/db/models/sql/query.py", line 1240, in _add_q
    current_negated=current_negated)
  File "/Library/Python/2.7/site-packages/django/db/models/sql/query.py", line 1128, in build_filter
    lookup_type, value)
  File "/Library/Python/2.7/site-packages/django/db/models/fields/related.py", line 1107, in get_lookup_constraint
    value[index]), AND)
  File "/Library/Python/2.7/site-packages/django/utils/tree.py", line 104, in add
    data = self._prepare_data(data)
  File "/Library/Python/2.7/site-packages/django/db/models/sql/where.py", line 79, in _prepare_data
    value = obj.prepare(lookup_type, value)
  File "/Library/Python/2.7/site-packages/django/db/models/sql/where.py", line 352, in prepare
    return self.field.get_prep_lookup(lookup_type, value)
  File "/Library/Python/2.7/site-packages/django/db/models/fields/__init__.py", line 369, in get_prep_lookup
    return self.get_prep_value(value)
  File "/Library/Python/2.7/site-packages/django/db/models/fields/__init__.py", line 613, in get_prep_value
    return int(value)
TypeError: int() argument must be a string or a number, not 'AnonymousUser'
[06/Oct/2014 00:24:28] INFO [sos_app.views:22] about to test
[06/Oct/2014 00:24:28] INFO [sos_app.views:39] about to test
[06/Oct/2014 00:24:28] INFO [sos_app.views:47] about to test
[06/Oct/2014 00:24:28] INFO [sos_app.views:55] about to test
[06/Oct/2014 00:24:28] INFO [sos_app.views:28] AnonymousUser
[06/Oct/2014 00:24:28] INFO [sos_app.views:30] Returning filtered queryset
[06/Oct/2014 00:24:28] ERROR [django.request:224] Internal Server Error: /contacts/
Traceback (most recent call last):
  File "/Library/Python/2.7/site-packages/django/core/handlers/base.py", line 112, in get_response
    response = wrapped_callback(request, *callback_args, **callback_kwargs)
  File "/Library/Python/2.7/site-packages/django/views/decorators/csrf.py", line 57, in wrapped_view
    return view_func(*args, **kwargs)
  File "/Library/Python/2.7/site-packages/rest_framework/viewsets.py", line 79, in view
    return self.dispatch(request, *args, **kwargs)
  File "/Library/Python/2.7/site-packages/rest_framework/views.py", line 403, in dispatch
    response = self.handle_exception(exc)
  File "/Library/Python/2.7/site-packages/rest_framework/views.py", line 400, in dispatch
    response = handler(request, *args, **kwargs)
  File "/Library/Python/2.7/site-packages/rest_framework/mixins.py", line 76, in list
    self.object_list = self.filter_queryset(self.get_queryset())
  File "/Users/prateek/sjsu/sos/sos_app/views.py", line 31, in get_queryset
    return Contacts.objects.filter(owner=self.request.user)
  File "/Library/Python/2.7/site-packages/django/db/models/manager.py", line 163, in filter
    return self.get_queryset().filter(*args, **kwargs)
  File "/Library/Python/2.7/site-packages/django/db/models/query.py", line 593, in filter
    return self._filter_or_exclude(False, *args, **kwargs)
  File "/Library/Python/2.7/site-packages/django/db/models/query.py", line 611, in _filter_or_exclude
    clone.query.add_q(Q(*args, **kwargs))
  File "/Library/Python/2.7/site-packages/django/db/models/sql/query.py", line 1204, in add_q
    clause = self._add_q(where_part, used_aliases)
  File "/Library/Python/2.7/site-packages/django/db/models/sql/query.py", line 1240, in _add_q
    current_negated=current_negated)
  File "/Library/Python/2.7/site-packages/django/db/models/sql/query.py", line 1128, in build_filter
    lookup_type, value)
  File "/Library/Python/2.7/site-packages/django/db/models/fields/related.py", line 1107, in get_lookup_constraint
    value[index]), AND)
  File "/Library/Python/2.7/site-packages/django/utils/tree.py", line 104, in add
    data = self._prepare_data(data)
  File "/Library/Python/2.7/site-packages/django/db/models/sql/where.py", line 79, in _prepare_data
    value = obj.prepare(lookup_type, value)
  File "/Library/Python/2.7/site-packages/django/db/models/sql/where.py", line 352, in prepare
    return self.field.get_prep_lookup(lookup_type, value)
  File "/Library/Python/2.7/site-packages/django/db/models/fields/__init__.py", line 369, in get_prep_lookup
    return self.get_prep_value(value)
  File "/Library/Python/2.7/site-packages/django/db/models/fields/__init__.py", line 613, in get_prep_value
    return int(value)
TypeError: int() argument must be a string or a number, not 'AnonymousUser'
[06/Oct/2014 00:24:52] INFO [sos_app.views:28] AnonymousUser
[06/Oct/2014 00:24:52] INFO [sos_app.views:30] Returning filtered queryset
[06/Oct/2014 00:24:52] ERROR [django.request:224] Internal Server Error: /contacts/
Traceback (most recent call last):
  File "/Library/Python/2.7/site-packages/django/core/handlers/base.py", line 112, in get_response
    response = wrapped_callback(request, *callback_args, **callback_kwargs)
  File "/Library/Python/2.7/site-packages/django/views/decorators/csrf.py", line 57, in wrapped_view
    return view_func(*args, **kwargs)
  File "/Library/Python/2.7/site-packages/rest_framework/viewsets.py", line 79, in view
    return self.dispatch(request, *args, **kwargs)
  File "/Library/Python/2.7/site-packages/rest_framework/views.py", line 403, in dispatch
    response = self.handle_exception(exc)
  File "/Library/Python/2.7/site-packages/rest_framework/views.py", line 400, in dispatch
    response = handler(request, *args, **kwargs)
  File "/Library/Python/2.7/site-packages/rest_framework/mixins.py", line 76, in list
    self.object_list = self.filter_queryset(self.get_queryset())
  File "/Users/prateek/sjsu/sos/sos_app/views.py", line 31, in get_queryset
    return Contacts.objects.filter(owner=self.request.user)
  File "/Library/Python/2.7/site-packages/django/db/models/manager.py", line 163, in filter
    return self.get_queryset().filter(*args, **kwargs)
  File "/Library/Python/2.7/site-packages/django/db/models/query.py", line 593, in filter
    return self._filter_or_exclude(False, *args, **kwargs)
  File "/Library/Python/2.7/site-packages/django/db/models/query.py", line 611, in _filter_or_exclude
    clone.query.add_q(Q(*args, **kwargs))
  File "/Library/Python/2.7/site-packages/django/db/models/sql/query.py", line 1204, in add_q
    clause = self._add_q(where_part, used_aliases)
  File "/Library/Python/2.7/site-packages/django/db/models/sql/query.py", line 1240, in _add_q
    current_negated=current_negated)
  File "/Library/Python/2.7/site-packages/django/db/models/sql/query.py", line 1128, in build_filter
    lookup_type, value)
  File "/Library/Python/2.7/site-packages/django/db/models/fields/related.py", line 1107, in get_lookup_constraint
    value[index]), AND)
  File "/Library/Python/2.7/site-packages/django/utils/tree.py", line 104, in add
    data = self._prepare_data(data)
  File "/Library/Python/2.7/site-packages/django/db/models/sql/where.py", line 79, in _prepare_data
    value = obj.prepare(lookup_type, value)
  File "/Library/Python/2.7/site-packages/django/db/models/sql/where.py", line 352, in prepare
    return self.field.get_prep_lookup(lookup_type, value)
  File "/Library/Python/2.7/site-packages/django/db/models/fields/__init__.py", line 369, in get_prep_lookup
    return self.get_prep_value(value)
  File "/Library/Python/2.7/site-packages/django/db/models/fields/__init__.py", line 613, in get_prep_value
    return int(value)
TypeError: int() argument must be a string or a number, not 'AnonymousUser'
[06/Oct/2014 00:26:35] INFO [sos_app.views:22] about to test
[06/Oct/2014 00:26:35] INFO [sos_app.views:39] about to test
[06/Oct/2014 00:26:35] INFO [sos_app.views:47] about to test
[06/Oct/2014 00:26:35] INFO [sos_app.views:55] about to test
[06/Oct/2014 00:26:35] INFO [sos_app.views:28] AnonymousUser
[06/Oct/2014 00:26:35] INFO [sos_app.views:33] Returning all contacts queryset
[06/Oct/2014 00:26:48] INFO [sos_app.views:28] admin
[06/Oct/2014 00:26:48] INFO [sos_app.views:33] Returning all contacts queryset
[06/Oct/2014 00:27:16] INFO [sos_app.views:28] AnonymousUser
[06/Oct/2014 00:27:16] INFO [sos_app.views:33] Returning all contacts queryset
[06/Oct/2014 00:27:22] INFO [sos_app.views:28] prateek
[06/Oct/2014 00:27:22] INFO [sos_app.views:33] Returning all contacts queryset
[06/Oct/2014 00:27:50] INFO [sos_app.views:22] about to test
[06/Oct/2014 00:27:50] INFO [sos_app.views:39] about to test
[06/Oct/2014 00:27:50] INFO [sos_app.views:47] about to test
[06/Oct/2014 00:27:50] INFO [sos_app.views:55] about to test
[06/Oct/2014 00:27:50] INFO [sos_app.views:28] <rest_framework.request.Request object at 0x106046d10>
[06/Oct/2014 00:27:50] INFO [sos_app.views:33] Returning all contacts queryset
[06/Oct/2014 00:28:17] INFO [sos_app.views:22] about to test
[06/Oct/2014 00:28:17] INFO [sos_app.views:39] about to test
[06/Oct/2014 00:28:17] INFO [sos_app.views:47] about to test
[06/Oct/2014 00:28:17] INFO [sos_app.views:55] about to test
[06/Oct/2014 00:28:17] ERROR [django.request:224] Internal Server Error: /contacts/
Traceback (most recent call last):
  File "/Library/Python/2.7/site-packages/django/core/handlers/base.py", line 112, in get_response
    response = wrapped_callback(request, *callback_args, **callback_kwargs)
  File "/Library/Python/2.7/site-packages/django/views/decorators/csrf.py", line 57, in wrapped_view
    return view_func(*args, **kwargs)
  File "/Library/Python/2.7/site-packages/rest_framework/viewsets.py", line 79, in view
    return self.dispatch(request, *args, **kwargs)
  File "/Library/Python/2.7/site-packages/rest_framework/views.py", line 403, in dispatch
    response = self.handle_exception(exc)
  File "/Library/Python/2.7/site-packages/rest_framework/views.py", line 400, in dispatch
    response = handler(request, *args, **kwargs)
  File "/Library/Python/2.7/site-packages/rest_framework/mixins.py", line 76, in list
    self.object_list = self.filter_queryset(self.get_queryset())
  File "/Users/prateek/sjsu/sos/sos_app/views.py", line 28, in get_queryset
    logger.info(self.request.user())
TypeError: 'SimpleLazyObject' object is not callable
[06/Oct/2014 00:28:32] INFO [sos_app.views:22] about to test
[06/Oct/2014 00:28:32] INFO [sos_app.views:39] about to test
[06/Oct/2014 00:28:32] INFO [sos_app.views:47] about to test
[06/Oct/2014 00:28:32] INFO [sos_app.views:55] about to test
[06/Oct/2014 00:28:32] INFO [sos_app.views:28] prateek
[06/Oct/2014 00:28:32] INFO [sos_app.views:33] Returning all contacts queryset
[06/Oct/2014 00:28:54] INFO [sos_app.views:22] about to test
[06/Oct/2014 00:28:54] INFO [sos_app.views:39] about to test
[06/Oct/2014 00:28:54] INFO [sos_app.views:47] about to test
[06/Oct/2014 00:28:54] INFO [sos_app.views:55] about to test
[06/Oct/2014 00:28:54] INFO [sos_app.views:28] False
[06/Oct/2014 00:28:54] INFO [sos_app.views:33] Returning all contacts queryset
[06/Oct/2014 00:29:22] INFO [sos_app.views:22] about to test
[06/Oct/2014 00:29:22] INFO [sos_app.views:40] about to test
[06/Oct/2014 00:29:22] INFO [sos_app.views:48] about to test
[06/Oct/2014 00:29:22] INFO [sos_app.views:56] about to test
[06/Oct/2014 00:29:22] INFO [sos_app.views:29] False
[06/Oct/2014 00:29:22] INFO [sos_app.views:34] Returning all contacts queryset
[06/Oct/2014 00:29:36] INFO [sos_app.views:22] about to test
[06/Oct/2014 00:29:36] INFO [sos_app.views:40] about to test
[06/Oct/2014 00:29:36] INFO [sos_app.views:48] about to test
[06/Oct/2014 00:29:36] INFO [sos_app.views:56] about to test
[06/Oct/2014 00:29:36] INFO [sos_app.views:29] prateek
[06/Oct/2014 00:29:36] INFO [sos_app.views:34] Returning all contacts queryset
[06/Oct/2014 00:31:34] INFO [sos_app.views:22] about to test
[06/Oct/2014 00:31:34] INFO [sos_app.views:39] about to test
[06/Oct/2014 00:31:34] INFO [sos_app.views:47] about to test
[06/Oct/2014 00:31:34] INFO [sos_app.views:55] about to test
[06/Oct/2014 00:31:34] INFO [sos_app.views:30] Returning filtered queryset
[06/Oct/2014 00:31:45] INFO [sos_app.views:33] Returning all contacts queryset
[06/Oct/2014 00:31:47] INFO [sos_app.views:33] Returning all contacts queryset
[06/Oct/2014 00:31:52] INFO [sos_app.views:30] Returning filtered queryset
[06/Oct/2014 00:35:05] INFO [sos_app.views:22] about to test
[06/Oct/2014 00:35:05] INFO [sos_app.views:38] about to test
[06/Oct/2014 00:35:05] INFO [sos_app.views:46] about to test
[06/Oct/2014 00:35:05] INFO [sos_app.views:54] about to test
[06/Oct/2014 00:35:05] INFO [sos_app.views:32] Returning filtered queryset
[06/Oct/2014 00:35:20] INFO [sos_app.views:22] about to test
[06/Oct/2014 00:35:20] INFO [sos_app.views:32] about to test
[06/Oct/2014 00:35:20] INFO [sos_app.views:40] about to test
[06/Oct/2014 00:35:20] INFO [sos_app.views:48] about to test
[06/Oct/2014 00:35:49] INFO [sos_app.views:22] about to test
[06/Oct/2014 00:35:49] INFO [sos_app.views:32] about to test
[06/Oct/2014 00:35:49] INFO [sos_app.views:40] about to test
[06/Oct/2014 00:35:49] INFO [sos_app.views:48] about to test
[06/Oct/2014 00:37:01] INFO [sos_app.views:22] about to test
[06/Oct/2014 00:37:01] INFO [sos_app.views:39] about to test
[06/Oct/2014 00:37:01] INFO [sos_app.views:47] about to test
[06/Oct/2014 00:37:01] INFO [sos_app.views:55] about to test
[06/Oct/2014 00:37:01] INFO [sos_app.views:32] Returning filtered queryset
[06/Oct/2014 00:37:17] INFO [sos_app.views:22] about to test
[06/Oct/2014 00:37:17] INFO [sos_app.views:35] about to test
[06/Oct/2014 00:37:17] INFO [sos_app.views:43] about to test
[06/Oct/2014 00:37:17] INFO [sos_app.views:51] about to test
[06/Oct/2014 00:37:24] INFO [sos_app.views:28] Returning filtered queryset
[06/Oct/2014 00:37:32] INFO [sos_app.views:28] Returning filtered queryset
[06/Oct/2014 00:37:49] INFO [sos_app.views:22] about to test
[06/Oct/2014 00:37:49] INFO [sos_app.views:35] about to test
[06/Oct/2014 00:37:49] INFO [sos_app.views:43] about to test
[06/Oct/2014 00:37:49] INFO [sos_app.views:51] about to test
[06/Oct/2014 00:37:49] INFO [sos_app.views:28] Returning filtered queryset
[06/Oct/2014 00:37:52] INFO [sos_app.views:28] Returning filtered queryset
[06/Oct/2014 00:37:52] ERROR [django.request:224] Internal Server Error: /contacts/
Traceback (most recent call last):
  File "/Library/Python/2.7/site-packages/django/core/handlers/base.py", line 112, in get_response
    response = wrapped_callback(request, *callback_args, **callback_kwargs)
  File "/Library/Python/2.7/site-packages/django/views/decorators/csrf.py", line 57, in wrapped_view
    return view_func(*args, **kwargs)
  File "/Library/Python/2.7/site-packages/rest_framework/viewsets.py", line 79, in view
    return self.dispatch(request, *args, **kwargs)
  File "/Library/Python/2.7/site-packages/rest_framework/views.py", line 403, in dispatch
    response = self.handle_exception(exc)
  File "/Library/Python/2.7/site-packages/rest_framework/views.py", line 400, in dispatch
    response = handler(request, *args, **kwargs)
  File "/Library/Python/2.7/site-packages/rest_framework/mixins.py", line 76, in list
    self.object_list = self.filter_queryset(self.get_queryset())
  File "/Users/prateek/sjsu/sos/sos_app/views.py", line 29, in get_queryset
    return Contacts.objects.filter(owner=self.request.user)
  File "/Library/Python/2.7/site-packages/django/db/models/manager.py", line 163, in filter
    return self.get_queryset().filter(*args, **kwargs)
  File "/Library/Python/2.7/site-packages/django/db/models/query.py", line 593, in filter
    return self._filter_or_exclude(False, *args, **kwargs)
  File "/Library/Python/2.7/site-packages/django/db/models/query.py", line 611, in _filter_or_exclude
    clone.query.add_q(Q(*args, **kwargs))
  File "/Library/Python/2.7/site-packages/django/db/models/sql/query.py", line 1204, in add_q
    clause = self._add_q(where_part, used_aliases)
  File "/Library/Python/2.7/site-packages/django/db/models/sql/query.py", line 1240, in _add_q
    current_negated=current_negated)
  File "/Library/Python/2.7/site-packages/django/db/models/sql/query.py", line 1128, in build_filter
    lookup_type, value)
  File "/Library/Python/2.7/site-packages/django/db/models/fields/related.py", line 1107, in get_lookup_constraint
    value[index]), AND)
  File "/Library/Python/2.7/site-packages/django/utils/tree.py", line 104, in add
    data = self._prepare_data(data)
  File "/Library/Python/2.7/site-packages/django/db/models/sql/where.py", line 79, in _prepare_data
    value = obj.prepare(lookup_type, value)
  File "/Library/Python/2.7/site-packages/django/db/models/sql/where.py", line 352, in prepare
    return self.field.get_prep_lookup(lookup_type, value)
  File "/Library/Python/2.7/site-packages/django/db/models/fields/__init__.py", line 369, in get_prep_lookup
    return self.get_prep_value(value)
  File "/Library/Python/2.7/site-packages/django/db/models/fields/__init__.py", line 613, in get_prep_value
    return int(value)
TypeError: int() argument must be a string or a number, not 'AnonymousUser'
[06/Oct/2014 00:38:02] INFO [sos_app.views:22] about to test
[06/Oct/2014 00:38:02] INFO [sos_app.views:35] about to test
[06/Oct/2014 00:38:02] INFO [sos_app.views:43] about to test
[06/Oct/2014 00:38:02] INFO [sos_app.views:51] about to test
[06/Oct/2014 00:38:27] INFO [sos_app.views:22] about to test
[06/Oct/2014 00:38:27] INFO [sos_app.views:35] about to test
[06/Oct/2014 00:38:27] INFO [sos_app.views:43] about to test
[06/Oct/2014 00:38:27] INFO [sos_app.views:51] about to test
[06/Oct/2014 00:38:27] INFO [sos_app.views:28] Returning filtered queryset
[06/Oct/2014 00:38:27] ERROR [django.request:224] Internal Server Error: /contacts/
Traceback (most recent call last):
  File "/Library/Python/2.7/site-packages/django/core/handlers/base.py", line 112, in get_response
    response = wrapped_callback(request, *callback_args, **callback_kwargs)
  File "/Library/Python/2.7/site-packages/django/views/decorators/csrf.py", line 57, in wrapped_view
    return view_func(*args, **kwargs)
  File "/Library/Python/2.7/site-packages/rest_framework/viewsets.py", line 79, in view
    return self.dispatch(request, *args, **kwargs)
  File "/Library/Python/2.7/site-packages/rest_framework/views.py", line 403, in dispatch
    response = self.handle_exception(exc)
  File "/Library/Python/2.7/site-packages/rest_framework/views.py", line 400, in dispatch
    response = handler(request, *args, **kwargs)
  File "/Library/Python/2.7/site-packages/rest_framework/mixins.py", line 76, in list
    self.object_list = self.filter_queryset(self.get_queryset())
  File "/Users/prateek/sjsu/sos/sos_app/views.py", line 29, in get_queryset
    return Contacts.objects.filter(owner=self.request.user)
  File "/Library/Python/2.7/site-packages/django/db/models/manager.py", line 163, in filter
    return self.get_queryset().filter(*args, **kwargs)
  File "/Library/Python/2.7/site-packages/django/db/models/query.py", line 593, in filter
    return self._filter_or_exclude(False, *args, **kwargs)
  File "/Library/Python/2.7/site-packages/django/db/models/query.py", line 611, in _filter_or_exclude
    clone.query.add_q(Q(*args, **kwargs))
  File "/Library/Python/2.7/site-packages/django/db/models/sql/query.py", line 1204, in add_q
    clause = self._add_q(where_part, used_aliases)
  File "/Library/Python/2.7/site-packages/django/db/models/sql/query.py", line 1240, in _add_q
    current_negated=current_negated)
  File "/Library/Python/2.7/site-packages/django/db/models/sql/query.py", line 1128, in build_filter
    lookup_type, value)
  File "/Library/Python/2.7/site-packages/django/db/models/fields/related.py", line 1107, in get_lookup_constraint
    value[index]), AND)
  File "/Library/Python/2.7/site-packages/django/utils/tree.py", line 104, in add
    data = self._prepare_data(data)
  File "/Library/Python/2.7/site-packages/django/db/models/sql/where.py", line 79, in _prepare_data
    value = obj.prepare(lookup_type, value)
  File "/Library/Python/2.7/site-packages/django/db/models/sql/where.py", line 352, in prepare
    return self.field.get_prep_lookup(lookup_type, value)
  File "/Library/Python/2.7/site-packages/django/db/models/fields/__init__.py", line 369, in get_prep_lookup
    return self.get_prep_value(value)
  File "/Library/Python/2.7/site-packages/django/db/models/fields/__init__.py", line 613, in get_prep_value
    return int(value)
TypeError: int() argument must be a string or a number, not 'AnonymousUser'
[06/Oct/2014 00:38:33] INFO [sos_app.views:22] about to test
[06/Oct/2014 00:38:33] INFO [sos_app.views:35] about to test
[06/Oct/2014 00:38:33] INFO [sos_app.views:43] about to test
[06/Oct/2014 00:38:33] INFO [sos_app.views:51] about to test
[06/Oct/2014 00:38:57] INFO [sos_app.views:22] about to test
[06/Oct/2014 00:38:57] INFO [sos_app.views:35] about to test
[06/Oct/2014 00:38:57] INFO [sos_app.views:43] about to test
[06/Oct/2014 00:38:57] INFO [sos_app.views:51] about to test
[06/Oct/2014 00:38:57] INFO [sos_app.views:28] Returning filtered queryset
[06/Oct/2014 00:38:57] ERROR [django.request:224] Internal Server Error: /contacts/
Traceback (most recent call last):
  File "/Library/Python/2.7/site-packages/django/core/handlers/base.py", line 112, in get_response
    response = wrapped_callback(request, *callback_args, **callback_kwargs)
  File "/Library/Python/2.7/site-packages/django/views/decorators/csrf.py", line 57, in wrapped_view
    return view_func(*args, **kwargs)
  File "/Library/Python/2.7/site-packages/rest_framework/viewsets.py", line 79, in view
    return self.dispatch(request, *args, **kwargs)
  File "/Library/Python/2.7/site-packages/rest_framework/views.py", line 403, in dispatch
    response = self.handle_exception(exc)
  File "/Library/Python/2.7/site-packages/rest_framework/views.py", line 400, in dispatch
    response = handler(request, *args, **kwargs)
  File "/Library/Python/2.7/site-packages/rest_framework/mixins.py", line 76, in list
    self.object_list = self.filter_queryset(self.get_queryset())
  File "/Users/prateek/sjsu/sos/sos_app/views.py", line 29, in get_queryset
    return Contacts.objects.filter(owner=self.request.user)
  File "/Library/Python/2.7/site-packages/django/db/models/manager.py", line 163, in filter
    return self.get_queryset().filter(*args, **kwargs)
  File "/Library/Python/2.7/site-packages/django/db/models/query.py", line 593, in filter
    return self._filter_or_exclude(False, *args, **kwargs)
  File "/Library/Python/2.7/site-packages/django/db/models/query.py", line 611, in _filter_or_exclude
    clone.query.add_q(Q(*args, **kwargs))
  File "/Library/Python/2.7/site-packages/django/db/models/sql/query.py", line 1204, in add_q
    clause = self._add_q(where_part, used_aliases)
  File "/Library/Python/2.7/site-packages/django/db/models/sql/query.py", line 1240, in _add_q
    current_negated=current_negated)
  File "/Library/Python/2.7/site-packages/django/db/models/sql/query.py", line 1128, in build_filter
    lookup_type, value)
  File "/Library/Python/2.7/site-packages/django/db/models/fields/related.py", line 1107, in get_lookup_constraint
    value[index]), AND)
  File "/Library/Python/2.7/site-packages/django/utils/tree.py", line 104, in add
    data = self._prepare_data(data)
  File "/Library/Python/2.7/site-packages/django/db/models/sql/where.py", line 79, in _prepare_data
    value = obj.prepare(lookup_type, value)
  File "/Library/Python/2.7/site-packages/django/db/models/sql/where.py", line 352, in prepare
    return self.field.get_prep_lookup(lookup_type, value)
  File "/Library/Python/2.7/site-packages/django/db/models/fields/__init__.py", line 369, in get_prep_lookup
    return self.get_prep_value(value)
  File "/Library/Python/2.7/site-packages/django/db/models/fields/__init__.py", line 613, in get_prep_value
    return int(value)
TypeError: int() argument must be a string or a number, not 'AnonymousUser'
[06/Oct/2014 00:39:03] INFO [sos_app.views:22] about to test
[06/Oct/2014 00:39:03] INFO [sos_app.views:35] about to test
[06/Oct/2014 00:39:03] INFO [sos_app.views:43] about to test
[06/Oct/2014 00:39:03] INFO [sos_app.views:51] about to test
[06/Oct/2014 00:41:21] INFO [sos_app.views:22] about to test
[06/Oct/2014 00:41:21] INFO [sos_app.views:35] about to test
[06/Oct/2014 00:41:21] INFO [sos_app.views:43] about to test
[06/Oct/2014 00:41:21] INFO [sos_app.views:51] about to test
[06/Oct/2014 00:41:21] ERROR [django.request:224] Internal Server Error: /contacts/
Traceback (most recent call last):
  File "/Library/Python/2.7/site-packages/django/core/handlers/base.py", line 99, in get_response
    resolver_match = resolver.resolve(request.path_info)
  File "/Library/Python/2.7/site-packages/django/core/urlresolvers.py", line 337, in resolve
    for pattern in self.url_patterns:
  File "/Library/Python/2.7/site-packages/django/core/urlresolvers.py", line 365, in url_patterns
    patterns = getattr(self.urlconf_module, "urlpatterns", self.urlconf_module)
  File "/Library/Python/2.7/site-packages/django/core/urlresolvers.py", line 360, in urlconf_module
    self._urlconf_module = import_module(self.urlconf_name)
  File "/Library/Python/2.7/site-packages/django/utils/importlib.py", line 40, in import_module
    __import__(name)
  File "/Users/prateek/sjsu/sos/sos/urls.py", line 11, in <module>
    router.register(r'contacts', ContactsViewSet)
  File "/Library/Python/2.7/site-packages/rest_framework/routers.py", line 59, in register
    base_name = self.get_default_base_name(viewset)
  File "/Library/Python/2.7/site-packages/rest_framework/routers.py", line 140, in get_default_base_name
    assert model_cls, '`base_name` argument not specified, and could ' \
AssertionError: `base_name` argument not specified, and could not automatically determine the name from the viewset, as it does not have a `.queryset` attribute.
[06/Oct/2014 00:41:33] INFO [sos_app.views:22] about to test
[06/Oct/2014 00:41:33] INFO [sos_app.views:35] about to test
[06/Oct/2014 00:41:33] INFO [sos_app.views:43] about to test
[06/Oct/2014 00:41:33] INFO [sos_app.views:51] about to test
[06/Oct/2014 20:47:49] WARNING [django.request:143] Not Found: /favicon.ico
[06/Oct/2014 20:47:49] WARNING [django.request:143] Not Found: /favicon.ico
[09/Oct/2014 01:53:07] WARNING [django.request:143] Not Found: /favicon.ico
[09/Oct/2014 01:53:07] WARNING [django.request:143] Not Found: /favicon.ico
[09/Oct/2014 02:00:54] INFO [sos_app.views:28] Returning filtered queryset for Contacts
[09/Oct/2014 02:01:41] INFO [sos_app.views:28] Returning filtered queryset for Contacts
[09/Oct/2014 02:01:43] INFO [sos_app.views:28] Returning filtered queryset for Contacts
[11/Oct/2014 18:36:03] WARNING [django.request:143] Not Found: /favicon.ico
[11/Oct/2014 18:36:03] WARNING [django.request:143] Not Found: /favicon.ico
[17/Nov/2014 19:43:24] WARNING [django.request:143] Not Found: /favicon.ico
[17/Nov/2014 19:43:24] WARNING [django.request:143] Not Found: /favicon.ico
[17/Nov/2014 19:43:55] WARNING [django.request:143] Not Found: /favicon.ico
[17/Nov/2014 19:44:18] INFO [sos_app.views:28] Returning filtered queryset for Contacts
[17/Nov/2014 19:44:25] INFO [sos_app.views:28] Returning filtered queryset for Contacts
[17/Nov/2014 21:08:38] INFO [sos_app.views:40] Returning filtered queryset for mobile device object
[04/Dec/2014 15:18:27] WARNING [django.request:143] Not Found: /favicon.ico
[04/Dec/2014 15:18:27] WARNING [django.request:143] Not Found: /favicon.ico
[04/Dec/2014 15:18:41] ERROR [django.request:224] Internal Server Error: /api-auth/login/
Traceback (most recent call last):
  File "/Library/Python/2.7/site-packages/django/core/handlers/base.py", line 112, in get_response
    response = wrapped_callback(request, *callback_args, **callback_kwargs)
  File "/Library/Python/2.7/site-packages/django/views/decorators/debug.py", line 75, in sensitive_post_parameters_wrapper
    return view(request, *args, **kwargs)
  File "/Library/Python/2.7/site-packages/django/utils/decorators.py", line 99, in _wrapped_view
    response = view_func(request, *args, **kwargs)
  File "/Library/Python/2.7/site-packages/django/views/decorators/cache.py", line 52, in _wrapped_view_func
    response = view_func(request, *args, **kwargs)
  File "/Library/Python/2.7/site-packages/django/contrib/auth/views.py", line 36, in login
    if form.is_valid():
  File "/Library/Python/2.7/site-packages/django/forms/forms.py", line 129, in is_valid
    return self.is_bound and not bool(self.errors)
  File "/Library/Python/2.7/site-packages/django/forms/forms.py", line 121, in errors
    self.full_clean()
  File "/Library/Python/2.7/site-packages/django/forms/forms.py", line 274, in full_clean
    self._clean_form()
  File "/Library/Python/2.7/site-packages/django/forms/forms.py", line 300, in _clean_form
    self.cleaned_data = self.clean()
  File "/Library/Python/2.7/site-packages/django/contrib/auth/forms.py", line 189, in clean
    password=password)
  File "/Library/Python/2.7/site-packages/django/contrib/auth/__init__.py", line 49, in authenticate
    user = backend.authenticate(**credentials)
  File "/Library/Python/2.7/site-packages/django/contrib/auth/backends.py", line 16, in authenticate
    user = UserModel._default_manager.get_by_natural_key(username)
  File "/Library/Python/2.7/site-packages/django/contrib/auth/models.py", line 167, in get_by_natural_key
    return self.get(**{self.model.USERNAME_FIELD: username})
  File "/Library/Python/2.7/site-packages/django/db/models/manager.py", line 151, in get
    return self.get_queryset().get(*args, **kwargs)
  File "/Library/Python/2.7/site-packages/django/db/models/query.py", line 304, in get
    num = len(clone)
  File "/Library/Python/2.7/site-packages/django/db/models/query.py", line 77, in __len__
    self._fetch_all()
  File "/Library/Python/2.7/site-packages/django/db/models/query.py", line 857, in _fetch_all
    self._result_cache = list(self.iterator())
  File "/Library/Python/2.7/site-packages/django/db/models/query.py", line 220, in iterator
    for row in compiler.results_iter():
  File "/Library/Python/2.7/site-packages/django/db/models/sql/compiler.py", line 713, in results_iter
    for rows in self.execute_sql(MULTI):
  File "/Library/Python/2.7/site-packages/django/db/models/sql/compiler.py", line 785, in execute_sql
    cursor = self.connection.cursor()
  File "/Library/Python/2.7/site-packages/django/db/backends/__init__.py", line 160, in cursor
    cursor = self.make_debug_cursor(self._cursor())
  File "/Library/Python/2.7/site-packages/django/db/backends/__init__.py", line 132, in _cursor
    self.ensure_connection()
  File "/Library/Python/2.7/site-packages/django/db/backends/__init__.py", line 127, in ensure_connection
    self.connect()
  File "/Library/Python/2.7/site-packages/django/db/utils.py", line 99, in __exit__
    six.reraise(dj_exc_type, dj_exc_value, traceback)
  File "/Library/Python/2.7/site-packages/django/db/backends/__init__.py", line 127, in ensure_connection
    self.connect()
  File "/Library/Python/2.7/site-packages/django/db/backends/__init__.py", line 115, in connect
    self.connection = self.get_new_connection(conn_params)
  File "/Library/Python/2.7/site-packages/django/db/backends/mysql/base.py", line 435, in get_new_connection
    conn = Database.connect(**conn_params)
  File "/Library/Python/2.7/site-packages/MySQLdb/__init__.py", line 81, in Connect
    return Connection(*args, **kwargs)
  File "/Library/Python/2.7/site-packages/MySQLdb/connections.py", line 193, in __init__
    super(Connection, self).__init__(*args, **kwargs2)
OperationalError: (2002, "Can't connect to local MySQL server through socket '/tmp/mysql.sock' (2)")
[04/Dec/2014 15:25:33] WARNING [django.request:143] Not Found: /favicon.ico
[04/Dec/2014 15:27:33] WARNING [django.request:143] Not Found: /accounts/profile/
[04/Dec/2014 15:28:39] WARNING [django.request:143] Not Found: /accounts/profile/
[04/Dec/2014 15:29:16] WARNING [django.request:99] Forbidden (CSRF token missing or incorrect.): /api-auth/login/
[04/Dec/2014 15:29:29] WARNING [django.request:143] Not Found: /api-auth/login/users
[04/Dec/2014 16:00:44] ERROR [django.request:224] Internal Server Error: /api-token-auth/
Traceback (most recent call last):
  File "/Library/Python/2.7/site-packages/django/core/handlers/base.py", line 112, in get_response
    response = wrapped_callback(request, *callback_args, **callback_kwargs)
  File "/Library/Python/2.7/site-packages/django/views/decorators/csrf.py", line 57, in wrapped_view
    return view_func(*args, **kwargs)
  File "/Library/Python/2.7/site-packages/django/views/generic/base.py", line 69, in view
    return self.dispatch(request, *args, **kwargs)
  File "/Library/Python/2.7/site-packages/rest_framework/views.py", line 403, in dispatch
    response = self.handle_exception(exc)
  File "/Library/Python/2.7/site-packages/rest_framework/views.py", line 400, in dispatch
    response = handler(request, *args, **kwargs)
  File "/Library/Python/2.7/site-packages/rest_framework/authtoken/views.py", line 21, in post
    token, created = Token.objects.get_or_create(user=serializer.object['user'])
AttributeError: type object 'Token' has no attribute 'objects'
[04/Dec/2014 16:11:30] WARNING [django.request:143] Not Found: /favicon.ico
[04/Dec/2014 16:13:16] WARNING [django.request:99] Forbidden (CSRF token missing or incorrect.): /api-auth/login/
[04/Dec/2014 16:13:41] WARNING [django.request:143] Not Found: /api-auth/login/users
[04/Dec/2014 16:27:46] WARNING [django.request:99] Forbidden (CSRF token missing or incorrect.): /api-auth/login/
[04/Dec/2014 16:28:47] WARNING [django.request:143] Not Found: /accounts/profile/
[04/Dec/2014 23:25:35] ERROR [django.request:224] Internal Server Error: /users/
Traceback (most recent call last):
  File "/Library/Python/2.7/site-packages/django/core/handlers/base.py", line 112, in get_response
    response = wrapped_callback(request, *callback_args, **callback_kwargs)
  File "/Library/Python/2.7/site-packages/django/views/decorators/csrf.py", line 57, in wrapped_view
    return view_func(*args, **kwargs)
  File "/Library/Python/2.7/site-packages/rest_framework/viewsets.py", line 79, in view
    return self.dispatch(request, *args, **kwargs)
  File "/Library/Python/2.7/site-packages/rest_framework/views.py", line 403, in dispatch
    response = self.handle_exception(exc)
  File "/Library/Python/2.7/site-packages/rest_framework/views.py", line 391, in dispatch
    self.initial(request, *args, **kwargs)
  File "/Library/Python/2.7/site-packages/rest_framework/views.py", line 320, in initial
    self.perform_authentication(request)
  File "/Library/Python/2.7/site-packages/rest_framework/views.py", line 270, in perform_authentication
    request.user
  File "/Library/Python/2.7/site-packages/rest_framework/request.py", line 226, in user
    self._authenticate()
  File "/Library/Python/2.7/site-packages/rest_framework/request.py", line 401, in _authenticate
    user_auth_tuple = authenticator.authenticate(self)
  File "/Library/Python/2.7/site-packages/rest_framework/authentication.py", line 117, in authenticate
    if not user or not user.is_active:
  File "/Library/Python/2.7/site-packages/django/utils/functional.py", line 213, in inner
    self._setup()
  File "/Library/Python/2.7/site-packages/django/utils/functional.py", line 298, in _setup
    self._wrapped = self._setupfunc()
  File "/Library/Python/2.7/site-packages/django/contrib/auth/middleware.py", line 18, in <lambda>
    request.user = SimpleLazyObject(lambda: get_user(request))
  File "/Library/Python/2.7/site-packages/django/contrib/auth/middleware.py", line 10, in get_user
    request._cached_user = auth.get_user(request)
  File "/Library/Python/2.7/site-packages/django/contrib/auth/__init__.py", line 140, in get_user
    user_id = request.session[SESSION_KEY]
  File "/Library/Python/2.7/site-packages/django/contrib/sessions/backends/base.py", line 47, in __getitem__
    return self._session[key]
  File "/Library/Python/2.7/site-packages/django/contrib/sessions/backends/base.py", line 173, in _get_session
    self._session_cache = self.load()
  File "/Library/Python/2.7/site-packages/django/contrib/sessions/backends/db.py", line 20, in load
    expire_date__gt=timezone.now()
  File "/Library/Python/2.7/site-packages/django/db/models/manager.py", line 151, in get
    return self.get_queryset().get(*args, **kwargs)
  File "/Library/Python/2.7/site-packages/django/db/models/query.py", line 304, in get
    num = len(clone)
  File "/Library/Python/2.7/site-packages/django/db/models/query.py", line 77, in __len__
    self._fetch_all()
  File "/Library/Python/2.7/site-packages/django/db/models/query.py", line 857, in _fetch_all
    self._result_cache = list(self.iterator())
  File "/Library/Python/2.7/site-packages/django/db/models/query.py", line 220, in iterator
    for row in compiler.results_iter():
  File "/Library/Python/2.7/site-packages/django/db/models/sql/compiler.py", line 713, in results_iter
    for rows in self.execute_sql(MULTI):
  File "/Library/Python/2.7/site-packages/django/db/models/sql/compiler.py", line 785, in execute_sql
    cursor = self.connection.cursor()
  File "/Library/Python/2.7/site-packages/django/db/backends/__init__.py", line 160, in cursor
    cursor = self.make_debug_cursor(self._cursor())
  File "/Library/Python/2.7/site-packages/django/db/backends/__init__.py", line 132, in _cursor
    self.ensure_connection()
  File "/Library/Python/2.7/site-packages/django/db/backends/__init__.py", line 127, in ensure_connection
    self.connect()
  File "/Library/Python/2.7/site-packages/django/db/utils.py", line 99, in __exit__
    six.reraise(dj_exc_type, dj_exc_value, traceback)
  File "/Library/Python/2.7/site-packages/django/db/backends/__init__.py", line 127, in ensure_connection
    self.connect()
  File "/Library/Python/2.7/site-packages/django/db/backends/__init__.py", line 115, in connect
    self.connection = self.get_new_connection(conn_params)
  File "/Library/Python/2.7/site-packages/django/db/backends/mysql/base.py", line 435, in get_new_connection
    conn = Database.connect(**conn_params)
  File "/Library/Python/2.7/site-packages/MySQLdb/__init__.py", line 81, in Connect
    return Connection(*args, **kwargs)
  File "/Library/Python/2.7/site-packages/MySQLdb/connections.py", line 193, in __init__
    super(Connection, self).__init__(*args, **kwargs2)
OperationalError: (2002, "Can't connect to local MySQL server through socket '/tmp/mysql.sock' (2)")
[04/Dec/2014 23:25:35] WARNING [django.request:143] Not Found: /favicon.ico
[04/Dec/2014 23:31:45] WARNING [django.request:99] Forbidden (CSRF cookie not set.): /api-auth/login/
[04/Dec/2014 23:32:59] WARNING [django.request:99] Forbidden (CSRF cookie not set.): /api-auth/login/
[04/Dec/2014 23:35:59] WARNING [django.request:99] Forbidden (CSRF cookie not set.): /api-auth/login/
[04/Dec/2014 23:37:23] WARNING [django.request:99] Forbidden (CSRF cookie not set.): /api-auth/login/
[04/Dec/2014 23:38:14] WARNING [django.request:99] Forbidden (CSRF cookie not set.): /api-auth/login/
[04/Dec/2014 23:39:39] WARNING [django.request:99] Forbidden (CSRF cookie not set.): /api-auth/login/
[04/Dec/2014 23:44:21] WARNING [django.request:99] Forbidden (CSRF cookie not set.): /api-auth/login/
[04/Dec/2014 23:45:21] WARNING [django.request:99] Forbidden (CSRF cookie not set.): /api-auth/login/
[05/Dec/2014 11:46:03] ERROR [django.request:224] Internal Server Error: /api/auth/
Traceback (most recent call last):
  File "/Library/Python/2.7/site-packages/django/core/handlers/base.py", line 112, in get_response
    response = wrapped_callback(request, *callback_args, **callback_kwargs)
  File "/Library/Python/2.7/site-packages/django/views/decorators/csrf.py", line 57, in wrapped_view
    return view_func(*args, **kwargs)
  File "/Library/Python/2.7/site-packages/django/views/generic/base.py", line 69, in view
    return self.dispatch(request, *args, **kwargs)
  File "/Library/Python/2.7/site-packages/rest_framework/views.py", line 403, in dispatch
    response = self.handle_exception(exc)
  File "/Library/Python/2.7/site-packages/rest_framework/views.py", line 391, in dispatch
    self.initial(request, *args, **kwargs)
  File "/Library/Python/2.7/site-packages/rest_framework/views.py", line 321, in initial
    self.check_permissions(request)
  File "/Library/Python/2.7/site-packages/rest_framework/views.py", line 278, in check_permissions
    if not permission.has_permission(request, self):
  File "/Library/Python/2.7/site-packages/rest_framework/permissions.py", line 125, in has_permission
    assert model_cls, ('Cannot apply DjangoModelPermissions on a view that'
AssertionError: Cannot apply DjangoModelPermissions on a view that does not have `.model` or `.queryset` property.
[05/Dec/2014 11:46:32] WARNING [django.request:143] Not Found: /favicon.ico
[05/Dec/2014 11:49:56] ERROR [django.request:224] Internal Server Error: /api/auth
Traceback (most recent call last):
  File "/Library/Python/2.7/site-packages/django/core/handlers/base.py", line 88, in get_response
    response = middleware_method(request)
  File "/Library/Python/2.7/site-packages/django/middleware/common.py", line 81, in process_request
    "settings.") % (new_url[0], new_url[1]))
RuntimeError: You called this URL via POST, but the URL doesn't end in a slash and you have APPEND_SLASH set. Django can't redirect to the slash URL while maintaining POST data. Change your form to point to 192.168.2.216:8000/api/auth/ (note the trailing slash), or set APPEND_SLASH=False in your Django settings.
[05/Dec/2014 11:50:21] ERROR [django.request:224] Internal Server Error: /api/auth/
Traceback (most recent call last):
  File "/Library/Python/2.7/site-packages/django/core/handlers/base.py", line 112, in get_response
    response = wrapped_callback(request, *callback_args, **callback_kwargs)
  File "/Library/Python/2.7/site-packages/django/views/decorators/csrf.py", line 57, in wrapped_view
    return view_func(*args, **kwargs)
  File "/Library/Python/2.7/site-packages/django/views/generic/base.py", line 69, in view
    return self.dispatch(request, *args, **kwargs)
  File "/Library/Python/2.7/site-packages/rest_framework/views.py", line 403, in dispatch
    response = self.handle_exception(exc)
  File "/Library/Python/2.7/site-packages/rest_framework/views.py", line 391, in dispatch
    self.initial(request, *args, **kwargs)
  File "/Library/Python/2.7/site-packages/rest_framework/views.py", line 321, in initial
    self.check_permissions(request)
  File "/Library/Python/2.7/site-packages/rest_framework/views.py", line 278, in check_permissions
    if not permission.has_permission(request, self):
  File "/Library/Python/2.7/site-packages/rest_framework/permissions.py", line 125, in has_permission
    assert model_cls, ('Cannot apply DjangoModelPermissions on a view that'
AssertionError: Cannot apply DjangoModelPermissions on a view that does not have `.model` or `.queryset` property.
[05/Dec/2014 12:13:51] ERROR [django.request:224] Internal Server Error: /api/auth/
Traceback (most recent call last):
  File "/Library/Python/2.7/site-packages/django/core/handlers/base.py", line 112, in get_response
    response = wrapped_callback(request, *callback_args, **callback_kwargs)
  File "/Library/Python/2.7/site-packages/django/views/decorators/csrf.py", line 57, in wrapped_view
    return view_func(*args, **kwargs)
  File "/Library/Python/2.7/site-packages/django/views/generic/base.py", line 69, in view
    return self.dispatch(request, *args, **kwargs)
  File "/Library/Python/2.7/site-packages/rest_framework/views.py", line 403, in dispatch
    response = self.handle_exception(exc)
  File "/Library/Python/2.7/site-packages/rest_framework/views.py", line 391, in dispatch
    self.initial(request, *args, **kwargs)
  File "/Library/Python/2.7/site-packages/rest_framework/views.py", line 321, in initial
    self.check_permissions(request)
  File "/Library/Python/2.7/site-packages/rest_framework/views.py", line 278, in check_permissions
    if not permission.has_permission(request, self):
  File "/Library/Python/2.7/site-packages/rest_framework/permissions.py", line 125, in has_permission
    assert model_cls, ('Cannot apply DjangoModelPermissions on a view that'
AssertionError: Cannot apply DjangoModelPermissions on a view that does not have `.model` or `.queryset` property.
[05/Dec/2014 12:15:23] ERROR [django.request:224] Internal Server Error: /api/auth/
Traceback (most recent call last):
  File "/Library/Python/2.7/site-packages/django/core/handlers/base.py", line 112, in get_response
    response = wrapped_callback(request, *callback_args, **callback_kwargs)
  File "/Library/Python/2.7/site-packages/django/views/decorators/csrf.py", line 57, in wrapped_view
    return view_func(*args, **kwargs)
  File "/Library/Python/2.7/site-packages/rest_framework/viewsets.py", line 70, in view
    for method, action in actions.items():
AttributeError: 'NoneType' object has no attribute 'items'
[05/Dec/2014 13:12:10] WARNING [django.request:99] Forbidden (CSRF cookie not set.): /api-auth/login/
[05/Dec/2014 13:12:37] WARNING [django.request:99] Forbidden (CSRF cookie not set.): /api-auth/login/
[05/Dec/2014 16:31:07] WARNING [django.request:143] Not Found: /api/auth/
[05/Dec/2014 16:46:37] WARNING [django.request:143] Not Found: /api/auth/
[05/Dec/2014 16:47:48] WARNING [django.request:99] Forbidden (CSRF cookie not set.): /api-auth/login/
[05/Dec/2014 19:06:12] WARNING [django.request:143] Not Found: /favicon.ico
[05/Dec/2014 19:10:09] WARNING [django.request:143] Not Found: /favicon.ico
[05/Dec/2014 19:16:36] ERROR [django.request:224] Internal Server Error: /login/
Traceback (most recent call last):
  File "/Library/Python/2.7/site-packages/django/core/handlers/base.py", line 112, in get_response
    response = wrapped_callback(request, *callback_args, **callback_kwargs)
  File "/Library/Python/2.7/site-packages/django/views/decorators/csrf.py", line 57, in wrapped_view
    return view_func(*args, **kwargs)
  File "/Users/prateek/sjsu/sos/sos_app/login.py", line 17, in user_login
    print request.data
AttributeError: 'WSGIRequest' object has no attribute 'data'
[05/Dec/2014 19:19:47] ERROR [django.request:224] Internal Server Error: /login/
Traceback (most recent call last):
  File "/Library/Python/2.7/site-packages/django/core/handlers/base.py", line 130, in get_response
    raise ValueError("The view %s.%s didn't return an HttpResponse object." % (callback.__module__, view_name))
ValueError: The view sos_app.login.user_login didn't return an HttpResponse object.
[05/Dec/2014 19:25:39] WARNING [django.request:99] Forbidden (CSRF token missing or incorrect.): /api-auth/login/
[05/Dec/2014 19:25:48] WARNING [django.request:99] Forbidden (CSRF token missing or incorrect.): /api-auth/login/
[05/Dec/2014 19:26:29] WARNING [django.request:99] Forbidden (CSRF token missing or incorrect.): /api-auth/login/
[05/Dec/2014 19:26:32] WARNING [django.request:99] Forbidden (CSRF token missing or incorrect.): /api-auth/login/
[05/Dec/2014 19:26:45] WARNING [django.request:99] Forbidden (CSRF token missing or incorrect.): /api-auth/login/
[05/Dec/2014 19:26:54] WARNING [django.request:99] Forbidden (CSRF token missing or incorrect.): /api-auth/login/
[05/Dec/2014 19:29:53] WARNING [django.request:99] Forbidden (CSRF token missing or incorrect.): /api-auth/login/
[05/Dec/2014 19:29:59] WARNING [django.request:99] Forbidden (CSRF token missing or incorrect.): /api-auth/login/
[05/Dec/2014 19:30:39] WARNING [django.request:99] Forbidden (CSRF token missing or incorrect.): /api-auth/login/
[05/Dec/2014 19:35:25] WARNING [django.request:99] Forbidden (CSRF token missing or incorrect.): /api-auth/login/
[05/Dec/2014 19:35:34] WARNING [django.request:99] Forbidden (CSRF token missing or incorrect.): /api-auth/login/
[05/Dec/2014 19:35:51] WARNING [django.request:143] Not Found: /accounts/profile/
[05/Dec/2014 19:36:35] WARNING [django.request:143] Not Found: /favicon.ico
[05/Dec/2014 19:36:43] WARNING [django.request:99] Forbidden (CSRF token missing or incorrect.): /api-auth/login/
[05/Dec/2014 19:37:01] WARNING [django.request:143] Not Found: /accounts/profile/
[05/Dec/2014 21:24:03] ERROR [django.request:224] Internal Server Error: /users/register
Traceback (most recent call last):
  File "/Library/Python/2.7/site-packages/django/core/handlers/base.py", line 88, in get_response
    response = middleware_method(request)
  File "/Library/Python/2.7/site-packages/django/middleware/common.py", line 81, in process_request
    "settings.") % (new_url[0], new_url[1]))
RuntimeError: You called this URL via POST, but the URL doesn't end in a slash and you have APPEND_SLASH set. Django can't redirect to the slash URL while maintaining POST data. Change your form to point to localhost:8000/users/register/ (note the trailing slash), or set APPEND_SLASH=False in your Django settings.
[05/Dec/2014 21:26:18] ERROR [django.request:224] Internal Server Error: /register/
Traceback (most recent call last):
  File "/Library/Python/2.7/site-packages/django/core/handlers/base.py", line 99, in get_response
    resolver_match = resolver.resolve(request.path_info)
  File "/Library/Python/2.7/site-packages/django/core/urlresolvers.py", line 337, in resolve
    for pattern in self.url_patterns:
  File "/Library/Python/2.7/site-packages/django/core/urlresolvers.py", line 365, in url_patterns
    patterns = getattr(self.urlconf_module, "urlpatterns", self.urlconf_module)
  File "/Library/Python/2.7/site-packages/django/core/urlresolvers.py", line 360, in urlconf_module
    self._urlconf_module = import_module(self.urlconf_name)
  File "/Library/Python/2.7/site-packages/django/utils/importlib.py", line 40, in import_module
    __import__(name)
  File "/Users/prateek/sjsu/sos/sos/urls.py", line 21, in <module>
    url(r'^login/', login.user_login),
NameError: name 'login' is not defined
[05/Dec/2014 21:30:17] ERROR [django.request:224] Internal Server Error: /register/
Traceback (most recent call last):
  File "/Library/Python/2.7/site-packages/django/core/handlers/base.py", line 99, in get_response
    resolver_match = resolver.resolve(request.path_info)
  File "/Library/Python/2.7/site-packages/django/core/urlresolvers.py", line 337, in resolve
    for pattern in self.url_patterns:
  File "/Library/Python/2.7/site-packages/django/core/urlresolvers.py", line 365, in url_patterns
    patterns = getattr(self.urlconf_module, "urlpatterns", self.urlconf_module)
  File "/Library/Python/2.7/site-packages/django/core/urlresolvers.py", line 360, in urlconf_module
    self._urlconf_module = import_module(self.urlconf_name)
  File "/Library/Python/2.7/site-packages/django/utils/importlib.py", line 40, in import_module
    __import__(name)
  File "/Users/prateek/sjsu/sos/sos/urls.py", line 20, in <module>
    url(r'^register/', register.register),
AttributeError: 'module' object has no attribute 'register'
[05/Dec/2014 21:36:08] ERROR [django.request:224] Internal Server Error: /users/1/
Traceback (most recent call last):
  File "/Library/Python/2.7/site-packages/django/core/handlers/base.py", line 112, in get_response
    response = wrapped_callback(request, *callback_args, **callback_kwargs)
  File "/Library/Python/2.7/site-packages/django/views/decorators/csrf.py", line 57, in wrapped_view
    return view_func(*args, **kwargs)
  File "/Library/Python/2.7/site-packages/rest_framework/viewsets.py", line 79, in view
    return self.dispatch(request, *args, **kwargs)
  File "/Library/Python/2.7/site-packages/rest_framework/views.py", line 403, in dispatch
    response = self.handle_exception(exc)
  File "/Library/Python/2.7/site-packages/rest_framework/views.py", line 400, in dispatch
    response = handler(request, *args, **kwargs)
  File "/Library/Python/2.7/site-packages/rest_framework/mixins.py", line 106, in retrieve
    self.object = self.get_object()
  File "/Library/Python/2.7/site-packages/rest_framework/generics.py", line 349, in get_object
    self.check_object_permissions(self.request, obj)
  File "/Library/Python/2.7/site-packages/rest_framework/views.py", line 287, in check_object_permissions
    if not permission.has_object_permission(request, self, obj):
  File "/Users/prateek/sjsu/sos/sos_app/permissions.py", line 13, in has_object_permission
    if obj.owner == request.user:
AttributeError: 'User' object has no attribute 'owner'
[05/Dec/2014 21:36:12] ERROR [django.request:224] Internal Server Error: /users/1/
Traceback (most recent call last):
  File "/Library/Python/2.7/site-packages/django/core/handlers/base.py", line 112, in get_response
    response = wrapped_callback(request, *callback_args, **callback_kwargs)
  File "/Library/Python/2.7/site-packages/django/views/decorators/csrf.py", line 57, in wrapped_view
    return view_func(*args, **kwargs)
  File "/Library/Python/2.7/site-packages/rest_framework/viewsets.py", line 79, in view
    return self.dispatch(request, *args, **kwargs)
  File "/Library/Python/2.7/site-packages/rest_framework/views.py", line 403, in dispatch
    response = self.handle_exception(exc)
  File "/Library/Python/2.7/site-packages/rest_framework/views.py", line 400, in dispatch
    response = handler(request, *args, **kwargs)
  File "/Library/Python/2.7/site-packages/rest_framework/mixins.py", line 106, in retrieve
    self.object = self.get_object()
  File "/Library/Python/2.7/site-packages/rest_framework/generics.py", line 349, in get_object
    self.check_object_permissions(self.request, obj)
  File "/Library/Python/2.7/site-packages/rest_framework/views.py", line 287, in check_object_permissions
    if not permission.has_object_permission(request, self, obj):
  File "/Users/prateek/sjsu/sos/sos_app/permissions.py", line 13, in has_object_permission
    if obj.owner == request.user:
AttributeError: 'User' object has no attribute 'owner'
[05/Dec/2014 21:36:32] ERROR [django.request:224] Internal Server Error: /users/1/
Traceback (most recent call last):
  File "/Library/Python/2.7/site-packages/django/core/handlers/base.py", line 112, in get_response
    response = wrapped_callback(request, *callback_args, **callback_kwargs)
  File "/Library/Python/2.7/site-packages/django/views/decorators/csrf.py", line 57, in wrapped_view
    return view_func(*args, **kwargs)
  File "/Library/Python/2.7/site-packages/rest_framework/viewsets.py", line 79, in view
    return self.dispatch(request, *args, **kwargs)
  File "/Library/Python/2.7/site-packages/rest_framework/views.py", line 403, in dispatch
    response = self.handle_exception(exc)
  File "/Library/Python/2.7/site-packages/rest_framework/views.py", line 400, in dispatch
    response = handler(request, *args, **kwargs)
  File "/Library/Python/2.7/site-packages/rest_framework/mixins.py", line 106, in retrieve
    self.object = self.get_object()
  File "/Library/Python/2.7/site-packages/rest_framework/generics.py", line 349, in get_object
    self.check_object_permissions(self.request, obj)
  File "/Library/Python/2.7/site-packages/rest_framework/views.py", line 287, in check_object_permissions
    if not permission.has_object_permission(request, self, obj):
  File "/Users/prateek/sjsu/sos/sos_app/permissions.py", line 13, in has_object_permission
    if obj.owner == request.user:
AttributeError: 'User' object has no attribute 'owner'
[05/Dec/2014 21:36:47] WARNING [django.request:143] Not Found: /users/username/sharmaprateek
[05/Dec/2014 21:37:10] ERROR [django.request:224] Internal Server Error: /users/1/
Traceback (most recent call last):
  File "/Library/Python/2.7/site-packages/django/core/handlers/base.py", line 112, in get_response
    response = wrapped_callback(request, *callback_args, **callback_kwargs)
  File "/Library/Python/2.7/site-packages/django/views/decorators/csrf.py", line 57, in wrapped_view
    return view_func(*args, **kwargs)
  File "/Library/Python/2.7/site-packages/rest_framework/viewsets.py", line 79, in view
    return self.dispatch(request, *args, **kwargs)
  File "/Library/Python/2.7/site-packages/rest_framework/views.py", line 403, in dispatch
    response = self.handle_exception(exc)
  File "/Library/Python/2.7/site-packages/rest_framework/views.py", line 400, in dispatch
    response = handler(request, *args, **kwargs)
  File "/Library/Python/2.7/site-packages/rest_framework/mixins.py", line 106, in retrieve
    self.object = self.get_object()
  File "/Library/Python/2.7/site-packages/rest_framework/generics.py", line 349, in get_object
    self.check_object_permissions(self.request, obj)
  File "/Library/Python/2.7/site-packages/rest_framework/views.py", line 287, in check_object_permissions
    if not permission.has_object_permission(request, self, obj):
  File "/Users/prateek/sjsu/sos/sos_app/permissions.py", line 13, in has_object_permission
    if obj.owner == request.user:
AttributeError: 'User' object has no attribute 'owner'
[05/Dec/2014 21:41:27] ERROR [django.request:224] Internal Server Error: /register/
Traceback (most recent call last):
  File "/Library/Python/2.7/site-packages/django/core/handlers/base.py", line 112, in get_response
    response = wrapped_callback(request, *callback_args, **callback_kwargs)
  File "/Library/Python/2.7/site-packages/django/views/decorators/csrf.py", line 57, in wrapped_view
    return view_func(*args, **kwargs)
  File "/Library/Python/2.7/site-packages/django/views/generic/base.py", line 69, in view
    return self.dispatch(request, *args, **kwargs)
  File "/Library/Python/2.7/site-packages/rest_framework/views.py", line 403, in dispatch
    response = self.handle_exception(exc)
  File "/Library/Python/2.7/site-packages/rest_framework/views.py", line 391, in dispatch
    self.initial(request, *args, **kwargs)
  File "/Library/Python/2.7/site-packages/rest_framework/views.py", line 321, in initial
    self.check_permissions(request)
  File "/Library/Python/2.7/site-packages/rest_framework/views.py", line 277, in check_permissions
    for permission in self.get_permissions():
  File "/Library/Python/2.7/site-packages/rest_framework/views.py", line 230, in get_permissions
    return [permission() for permission in self.permission_classes]
TypeError: 'type' object is not iterable
[06/Dec/2014 04:20:24] ERROR [django.request:224] Internal Server Error: /register
Traceback (most recent call last):
  File "/Library/Python/2.7/site-packages/django/core/handlers/base.py", line 88, in get_response
    response = middleware_method(request)
  File "/Library/Python/2.7/site-packages/django/middleware/common.py", line 81, in process_request
    "settings.") % (new_url[0], new_url[1]))
RuntimeError: You called this URL via POST, but the URL doesn't end in a slash and you have APPEND_SLASH set. Django can't redirect to the slash URL while maintaining POST data. Change your form to point to 192.168.2.216:8000/register/ (note the trailing slash), or set APPEND_SLASH=False in your Django settings.
[06/Dec/2014 04:26:05] WARNING [django.request:143] Not Found: /favicon.ico
